Workbook

Sheet Cấu hình
A1: Cấu hình – điền MỘT LẦN, cả file tự cập nhật
A2: Ô nền vàng là ô nhập. Họ tên ở đây được dùng làm danh sách chọn ở mọi sheet.
A3: Tên nhóm | B3: Nhóm 05
A4: Tên đề tài | B4: Kiểm thử website ANYN
A6: STT | B6: Họ tên | C6: Vai trò | D6: Ghi chú | F6: Nhóm | G6: Người phụ trách (chọn trong danh sách) | H6: Phạm vi
A7: 1 | B7: Thái Hoàng Minh | C7: QA Lead / Test Manager | D7: Điều phối, Test Plan, Test Summary, slide, review | F7: Nhóm 1 | G7: =B8 -> Lâm Hoài An | H7: M1–M5 (F01–F23) và F49 bộ lọc nội dung
A8: 2 | B8: Lâm Hoài An | C8: Functional Tester 1 | D8: Nhóm chức năng 1 | F8: Nhóm 2 | G8: =B9 -> Nguyễn Phúc Khang | H8: M6–M10 (F24–F44) và Security M11 (F45–F48, F52)
A9: 3 | B9: Nguyễn Phúc Khang | C9: Functional Tester 2 | D9: Nhóm chức năng 2 + Security TC + Bug Report | F9: Phi chức năng | G9: =B11 -> Châu Minh Tuệ | H9: Tương thích (F50), hiệu năng (F51)
A10: 4 | B10: Võ Trường Hải | C10: Automation Tester | D10: 6 script tự động
A11: 5 | B11: Châu Minh Tuệ | C11: Performance/Security Tester | D11: Performance, Security, tương thích | F11: Muốn đổi người phụ trách một nhóm: bấm ô vàng cột G và chọn tên khác. Muốn chuyển một chức năng sang nhóm khác: đổi cột 'Nhóm' trong sheet Checklist cover.

Sheet Tổng quan
A1: Tổng quan – bảng điều khiển của nhóm (tự động)
A2: Mở sheet này mỗi tuần để biết nhóm đang ở đâu và việc gì cần xử lý.
D4: Tiến độ từng người
D5: Họ tên | E5: Vai trò | F5: TC được giao | G5: Đã chạy | H5: Pass | I5: Fail | J5: Blocked | K5: % hoàn thành | L5: Lỗi đã báo | M5: Giờ đóng góp
D6: =IF('Cấu hình'!B7="","",'Cấu hình'!B7) -> Thái Hoàng Minh | E6: =IF('Cấu hình'!C7="","",'Cấu hình'!C7) -> QA Lead / Test Manager | F6: =IF(D6="","",COUNTIF('Test Cases'!$G$5:$G$300,D6)) -> 0 | G6: =IF(D6="","",F6-COUNTIFS('Test Cases'!$G$5:$G$300,D6,'Test Cases'!$T$5:$T$300,"Not Run")) -> 0 | H6: =IF(D6="","",COUNTIFS('Test Cases'!$G$5:$G$300,D6,'Test Cases'!$T$5:$T$300,"Pass")) -> 0 | I6: =IF(D6="","",COUNTIFS('Test Cases'!$G$5:$G$300,D6,'Test Cases'!$T$5:$T$300,"Fail")) -> 0 | J6: =IF(D6="","",COUNTIFS('Test Cases'!$G$5:$G$300,D6,'Test Cases'!$T$5:$T$300,"Blocked")) -> 0 | K6: =IF(OR(D6="",F6=0),0,G6/F6) -> 0 | L6: =IF(D6="","",COUNTIF('Bug Log'!$L$5:$L$154,D6)) -> 0 | M6: =IF(D6="","",SUMIF('Contribution Log'!$C$5:$C$204,D6,'Contribution Log'!$G$5:$G$204)) -> 0
D7: =IF('Cấu hình'!B8="","",'Cấu hình'!B8) -> Lâm Hoài An | E7: =IF('Cấu hình'!C8="","",'Cấu hình'!C8) -> Functional Tester 1 | F7: =IF(D7="","",COUNTIF('Test Cases'!$G$5:$G$300,D7)) -> 49 | G7: =IF(D7="","",F7-COUNTIFS('Test Cases'!$G$5:$G$300,D7,'Test Cases'!$T$5:$T$300,"Not Run")) -> 0 | H7: =IF(D7="","",COUNTIFS('Test Cases'!$G$5:$G$300,D7,'Test Cases'!$T$5:$T$300,"Pass")) -> 0 | I7: =IF(D7="","",COUNTIFS('Test Cases'!$G$5:$G$300,D7,'Test Cases'!$T$5:$T$300,"Fail")) -> 0 | J7: =IF(D7="","",COUNTIFS('Test Cases'!$G$5:$G$300,D7,'Test Cases'!$T$5:$T$300,"Blocked")) -> 0 | K7: =IF(OR(D7="",F7=0),0,G7/F7) -> 0 | L7: =IF(D7="","",COUNTIF('Bug Log'!$L$5:$L$154,D7)) -> 0 | M7: =IF(D7="","",SUMIF('Contribution Log'!$C$5:$C$204,D7,'Contribution Log'!$G$5:$G$204)) -> 0
D8: =IF('Cấu hình'!B9="","",'Cấu hình'!B9) -> Nguyễn Phúc Khang | E8: =IF('Cấu hình'!C9="","",'Cấu hình'!C9) -> Functional Tester 2 | F8: =IF(D8="","",COUNTIF('Test Cases'!$G$5:$G$300,D8)) -> 49 | G8: =IF(D8="","",F8-COUNTIFS('Test Cases'!$G$5:$G$300,D8,'Test Cases'!$T$5:$T$300,"Not Run")) -> 0 | H8: =IF(D8="","",COUNTIFS('Test Cases'!$G$5:$G$300,D8,'Test Cases'!$T$5:$T$300,"Pass")) -> 0 | I8: =IF(D8="","",COUNTIFS('Test Cases'!$G$5:$G$300,D8,'Test Cases'!$T$5:$T$300,"Fail")) -> 0 | J8: =IF(D8="","",COUNTIFS('Test Cases'!$G$5:$G$300,D8,'Test Cases'!$T$5:$T$300,"Blocked")) -> 0 | K8: =IF(OR(D8="",F8=0),0,G8/F8) -> 0 | L8: =IF(D8="","",COUNTIF('Bug Log'!$L$5:$L$154,D8)) -> 0 | M8: =IF(D8="","",SUMIF('Contribution Log'!$C$5:$C$204,D8,'Contribution Log'!$G$5:$G$204)) -> 0
D9: =IF('Cấu hình'!B10="","",'Cấu hình'!B10) -> Võ Trường Hải | E9: =IF('Cấu hình'!C10="","",'Cấu hình'!C10) -> Automation Tester | F9: =IF(D9="","",COUNTIF('Test Cases'!$G$5:$G$300,D9)) -> 0 | G9: =IF(D9="","",F9-COUNTIFS('Test Cases'!$G$5:$G$300,D9,'Test Cases'!$T$5:$T$300,"Not Run")) -> 0 | H9: =IF(D9="","",COUNTIFS('Test Cases'!$G$5:$G$300,D9,'Test Cases'!$T$5:$T$300,"Pass")) -> 0 | I9: =IF(D9="","",COUNTIFS('Test Cases'!$G$5:$G$300,D9,'Test Cases'!$T$5:$T$300,"Fail")) -> 0 | J9: =IF(D9="","",COUNTIFS('Test Cases'!$G$5:$G$300,D9,'Test Cases'!$T$5:$T$300,"Blocked")) -> 0 | K9: =IF(OR(D9="",F9=0),0,G9/F9) -> 0 | L9: =IF(D9="","",COUNTIF('Bug Log'!$L$5:$L$154,D9)) -> 0 | M9: =IF(D9="","",SUMIF('Contribution Log'!$C$5:$C$204,D9,'Contribution Log'!$G$5:$G$204)) -> 0
D10: =IF('Cấu hình'!B11="","",'Cấu hình'!B11) -> Châu Minh Tuệ | E10: =IF('Cấu hình'!C11="","",'Cấu hình'!C11) -> Performance/Security Tester | F10: =IF(D10="","",COUNTIF('Test Cases'!$G$5:$G$300,D10)) -> 2 | G10: =IF(D10="","",F10-COUNTIFS('Test Cases'!$G$5:$G$300,D10,'Test Cases'!$T$5:$T$300,"Not Run")) -> 0 | H10: =IF(D10="","",COUNTIFS('Test Cases'!$G$5:$G$300,D10,'Test Cases'!$T$5:$T$300,"Pass")) -> 0 | I10: =IF(D10="","",COUNTIFS('Test Cases'!$G$5:$G$300,D10,'Test Cases'!$T$5:$T$300,"Fail")) -> 0 | J10: =IF(D10="","",COUNTIFS('Test Cases'!$G$5:$G$300,D10,'Test Cases'!$T$5:$T$300,"Blocked")) -> 0 | K10: =IF(OR(D10="",F10=0),0,G10/F10) -> 0 | L10: =IF(D10="","",COUNTIF('Bug Log'!$L$5:$L$154,D10)) -> 0 | M10: =IF(D10="","",SUMIF('Contribution Log'!$C$5:$C$204,D10,'Contribution Log'!$G$5:$G$204)) -> 0
A15: Cảnh báo – việc cần xử lý
A16: Cảnh báo | B16: Số lượng | C16: Tình trạng | D16: Việc cần làm | E16: Ai xử lý
A17: TC Fail nhưng chưa có Bug ID | B17: =COUNTIFS('Test Cases'!$A$5:$A$300,"<>",'Test Cases'!$T$5:$T$300,"Fail",'Test Cases'!$U$5:$U$300,"") -> 0 | C17: =IF(B17=0,"✔ OK","⚠ Cần xử lý") -> ✔ OK | D17: Mở Bug Log ghi lỗi rồi chọn Bug ID trong Test Cases | E17: Người chạy TC đó
A18: TC đã chạy nhưng thiếu ngày test | B18: =COUNTIFS('Test Cases'!$A$5:$A$300,"<>",'Test Cases'!$T$5:$T$300,"<>Not Run",'Test Cases'!$R$5:$R$300,"") -> 0 | C18: =IF(B18=0,"✔ OK","⚠ Cần xử lý") -> ✔ OK | D18: Điền ngày (Ctrl + ;) | E18: Người chạy TC đó
A19: TC P1 chưa chạy | B19: =COUNTIFS('Test Cases'!$O$5:$O$300,"P1",'Test Cases'!$T$5:$T$300,"Not Run") -> 72 | C19: =IF(B19=0,"✔ OK","⚠ Cần xử lý") -> ⚠ Cần xử lý | D19: Ưu tiên chạy P1 trước | E19: Người phụ trách TC
A20: TC đang Blocked | B20: =COUNTIF('Test Cases'!$T$5:$T$300,"Blocked") -> 0 | C20: =IF(B20=0,"✔ OK","⚠ Cần xử lý") -> ✔ OK | D20: Xử lý lỗi chặn rồi chạy lại | E20: Khang + người chạy
A21: Chức năng chưa có test case | B21: =COUNTIF('Checklist cover'!M5:M56,"CHƯA CÓ TC") -> 0 | C21: =IF(B21=0,"✔ OK","⚠ Cần xử lý") -> ✔ OK | D21: Thêm TC cho chức năng đó | E21: Người phụ trách chức năng
A22: Lỗi Fixed đang chờ Verify | B22: =COUNTIF('Bug Log'!K5:K154,"Fixed") -> 0 | C22: =IF(B22=0,"✔ OK","⚠ Cần xử lý") -> ✔ OK | D22: Chạy lại TC, đúng thì Verified | E22: Người báo lỗi
A23: Lỗi Critical/High còn mở | B23: =SUMPRODUCT((('Bug Log'!$I$5:$I$154="Critical")+('Bug Log'!$I$5:$I$154="High"))*('Bug Log'!$K$5:$K$154<>"Closed")*('Bug Log'!$K$5:$K$154<>"Verified")*('Bug Log'!$K$5:$K$154<>"Rejected")*('Bug Log'!$E$5:$E$154<>"")) -> 0 | C23: =IF(B23=0,"✔ OK","⚠ Cần xử lý") -> ✔ OK | D23: Họp triage, gán người sửa | E23: Khang + Minh
A24: Script automation chưa chạy xong 3 lần | B24: =COUNTIF(Automation!J5:J12,"Not Run") -> 6 | C24: =IF(B24=0,"✔ OK","⚠ Cần xử lý") -> ⚠ Cần xử lý | D24: Chạy và ghi kết quả | E24: Hải
A25: Hạng mục Security chưa test | B25: =COUNTIF('Non-functional'!G5:G14,"Not Run") -> 10 | C25: =IF(B25=0,"✔ OK","⚠ Cần xử lý") -> ⚠ Cần xử lý | D25: Chạy và ghi kết quả | E25: Tuệ + Khang
A26: Tuần kế hoạch đang TRỄ | B26: =COUNTIF(#REF!,"TRỄ") -> #REF! | C26: =IF(B26=0,"✔ OK","⚠ Cần xử lý") -> #REF! | D26: Họp nhanh xử lý, cập nhật Trạng thái | E26: Minh

Sheet Checklist cover
A1: Checklist cover chức năng – ANYN
A2: Cột 'Nhóm' chọn được; 'Người phụ trách' tự lấy từ Cấu hình; số liệu tự tính. 'CHƯA CÓ TC' = còn sót chức năng.
A4: Mã CN | B4: Module | C4: Chức năng | D4: File / Vị trí | E4: Hành động / Điểm kiểm thử | F4: Nhóm | G4: Người phụ trách (tự động) | H4: Số TC | I4: Đã chạy | J4: Pass | K4: Fail | L4: % Đã chạy | M4: Trạng thái cover | N4: Đi tới TC
A5: F01 | B5: M1 – Tài khoản | C5: Đăng ký tài khoản | D5: pages/register.php | E5: POST register | F5: Nhóm 1 | G5: =IFERROR(VLOOKUP(F5,'Cấu hình'!$F$7:$G$9,2,FALSE()),"") -> Lâm Hoài An | H5: =COUNTIF('Test Cases'!$B$5:$B$300,A5) -> 3 | I5: =H5-COUNTIFS('Test Cases'!$B$5:$B$300,A5,'Test Cases'!$T$5:$T$300,"Not Run") -> 0 | J5: =COUNTIFS('Test Cases'!$B$5:$B$300,A5,'Test Cases'!$T$5:$T$300,"Pass") -> 0 | K5: =COUNTIFS('Test Cases'!$B$5:$B$300,A5,'Test Cases'!$T$5:$T$300,"Fail") -> 0 | L5: =IF(H5=0,0,I5/H5) -> 0 | M5: =IF(H5=0,"CHƯA CÓ TC","Đã cover") -> Đã cover | N5: =IFERROR(HYPERLINK("#'Test Cases'!A"&(MATCH(A5,'Test Cases'!$B$5:$B$300,0)+4),"→ xem TC"),"") -> → xem TC
A6: F02 | B6: M1 – Tài khoản | C6: Đăng nhập | D6: pages/login.php | E6: POST login | F6: Nhóm 1 | G6: =IFERROR(VLOOKUP(F6,'Cấu hình'!$F$7:$G$9,2,FALSE()),"") -> Lâm Hoài An | H6: =COUNTIF('Test Cases'!$B$5:$B$300,A6) -> 2 | I6: =H6-COUNTIFS('Test Cases'!$B$5:$B$300,A6,'Test Cases'!$T$5:$T$300,"Not Run") -> 0 | J6: =COUNTIFS('Test Cases'!$B$5:$B$300,A6,'Test Cases'!$T$5:$T$300,"Pass") -> 0 | K6: =COUNTIFS('Test Cases'!$B$5:$B$300,A6,'Test Cases'!$T$5:$T$300,"Fail") -> 0 | L6: =IF(H6=0,0,I6/H6) -> 0 | M6: =IF(H6=0,"CHƯA CÓ TC","Đã cover") -> Đã cover | N6: =IFERROR(HYPERLINK("#'Test Cases'!A"&(MATCH(A6,'Test Cases'!$B$5:$B$300,0)+4),"→ xem TC"),"") -> → xem TC
A7: F03 | B7: M1 – Tài khoản | C7: Chống dò mật khẩu (throttle) | D7: includes/auth.php | E7: loginIsThrottled: 5/email, 20/IP, 15 phút | F7: Nhóm 1 | G7: =IFERROR(VLOOKUP(F7,'Cấu hình'!$F$7:$G$9,2,FALSE()),"") -> Lâm Hoài An | H7: =COUNTIF('Test Cases'!$B$5:$B$300,A7) -> 2 | I7: =H7-COUNTIFS('Test Cases'!$B$5:$B$300,A7,'Test Cases'!$T$5:$T$300,"Not Run") -> 0 | J7: =COUNTIFS('Test Cases'!$B$5:$B$300,A7,'Test Cases'!$T$5:$T$300,"Pass") -> 0 | K7: =COUNTIFS('Test Cases'!$B$5:$B$300,A7,'Test Cases'!$T$5:$T$300,"Fail") -> 0 | L7: =IF(H7=0,0,I7/H7) -> 0 | M7: =IF(H7=0,"CHƯA CÓ TC","Đã cover") -> Đã cover | N7: =IFERROR(HYPERLINK("#'Test Cases'!A"&(MATCH(A7,'Test Cases'!$B$5:$B$300,0)+4),"→ xem TC"),"") -> → xem TC
A8: F04 | B8: M1 – Tài khoản | C8: Đăng xuất | D8: pages/logout.php | E8: GET logout | F8: Nhóm 1 | G8: =IFERROR(VLOOKUP(F8,'Cấu hình'!$F$7:$G$9,2,FALSE()),"") -> Lâm Hoài An | H8: =COUNTIF('Test Cases'!$B$5:$B$300,A8) -> 1 | I8: =H8-COUNTIFS('Test Cases'!$B$5:$B$300,A8,'Test Cases'!$T$5:$T$300,"Not Run") -> 0 | J8: =COUNTIFS('Test Cases'!$B$5:$B$300,A8,'Test Cases'!$T$5:$T$300,"Pass") -> 0 | K8: =COUNTIFS('Test Cases'!$B$5:$B$300,A8,'Test Cases'!$T$5:$T$300,"Fail") -> 0 | L8: =IF(H8=0,0,I8/H8) -> 0 | M8: =IF(H8=0,"CHƯA CÓ TC","Đã cover") -> Đã cover | N8: =IFERROR(HYPERLINK("#'Test Cases'!A"&(MATCH(A8,'Test Cases'!$B$5:$B$300,0)+4),"→ xem TC"),"") -> → xem TC
A9: F05 | B9: M1 – Tài khoản | C9: Quên mật khẩu | D9: pages/forgot_password.php | E9: POST email | F9: Nhóm 1 | G9: =IFERROR(VLOOKUP(F9,'Cấu hình'!$F$7:$G$9,2,FALSE()),"") -> Lâm Hoài An | H9: =COUNTIF('Test Cases'!$B$5:$B$300,A9) -> 2 | I9: =H9-COUNTIFS('Test Cases'!$B$5:$B$300,A9,'Test Cases'!$T$5:$T$300,"Not Run") -> 0 | J9: =COUNTIFS('Test Cases'!$B$5:$B$300,A9,'Test Cases'!$T$5:$T$300,"Pass") -> 0 | K9: =COUNTIFS('Test Cases'!$B$5:$B$300,A9,'Test Cases'!$T$5:$T$300,"Fail") -> 0 | L9: =IF(H9=0,0,I9/H9) -> 0 | M9: =IF(H9=0,"CHƯA CÓ TC","Đã cover") -> Đã cover | N9: =IFERROR(HYPERLINK("#'Test Cases'!A"&(MATCH(A9,'Test Cases'!$B$5:$B$300,0)+4),"→ xem TC"),"") -> → xem TC
A10: F06 | B10: M1 – Tài khoản | C10: Đặt lại mật khẩu bằng token | D10: pages/reset_password.php | E10: GET token / POST mật khẩu mới | F10: Nhóm 1 | G10: =IFERROR(VLOOKUP(F10,'Cấu hình'!$F$7:$G$9,2,FALSE()),"") -> Lâm Hoài An | H10: =COUNTIF('Test Cases'!$B$5:$B$300,A10) -> 2 | I10: =H10-COUNTIFS('Test Cases'!$B$5:$B$300,A10,'Test Cases'!$T$5:$T$300,"Not Run") -> 0 | J10: =COUNTIFS('Test Cases'!$B$5:$B$300,A10,'Test Cases'!$T$5:$T$300,"Pass") -> 0 | K10: =COUNTIFS('Test Cases'!$B$5:$B$300,A10,'Test Cases'!$T$5:$T$300,"Fail") -> 0 | L10: =IF(H10=0,0,I10/H10) -> 0 | M10: =IF(H10=0,"CHƯA CÓ TC","Đã cover") -> Đã cover | N10: =IFERROR(HYPERLINK("#'Test Cases'!A"&(MATCH(A10,'Test Cases'!$B$5:$B$300,0)+4),"→ xem TC"),"") -> → xem TC
A11: F07 | B11: M2 – Phân quyền | C11: Truy cập theo vai trò Guest/User/Admin | D11: includes/auth.php | E11: requireLogin / requireAdmin | F11: Nhóm 1 | G11: =IFERROR(VLOOKUP(F11,'Cấu hình'!$F$7:$G$9,2,FALSE()),"") -> Lâm Hoài An | H11: =COUNTIF('Test Cases'!$B$5:$B$300,A11) -> 4 | I11: =H11-COUNTIFS('Test Cases'!$B$5:$B$300,A11,'Test Cases'!$T$5:$T$300,"Not Run") -> 0 | J11: =COUNTIFS('Test Cases'!$B$5:$B$300,A11,'Test Cases'!$T$5:$T$300,"Pass") -> 0 | K11: =COUNTIFS('Test Cases'!$B$5:$B$300,A11,'Test Cases'!$T$5:$T$300,"Fail") -> 0 | L11: =IF(H11=0,0,I11/H11) -> 0 | M11: =IF(H11=0,"CHƯA CÓ TC","Đã cover") -> Đã cover | N11: =IFERROR(HYPERLINK("#'Test Cases'!A"&(MATCH(A11,'Test Cases'!$B$5:$B$300,0)+4),"→ xem TC"),"") -> → xem TC
A12: F08 | B12: M3 – Trang chủ & Tìm kiếm | C12: Trang chủ | D12: index.php | E12: GET | F12: Nhóm 1 | G12: =IFERROR(VLOOKUP(F12,'Cấu hình'!$F$7:$G$9,2,FALSE()),"") -> Lâm Hoài An | H12: =COUNTIF('Test Cases'!$B$5:$B$300,A12) -> 2 | I12: =H12-COUNTIFS('Test Cases'!$B$5:$B$300,A12,'Test Cases'!$T$5:$T$300,"Not Run") -> 0 | J12: =COUNTIFS('Test Cases'!$B$5:$B$300,A12,'Test Cases'!$T$5:$T$300,"Pass") -> 0 | K12: =COUNTIFS('Test Cases'!$B$5:$B$300,A12,'Test Cases'!$T$5:$T$300,"Fail") -> 0 | L12: =IF(H12=0,0,I12/H12) -> 0 | M12: =IF(H12=0,"CHƯA CÓ TC","Đã cover") -> Đã cover | N12: =IFERROR(HYPERLINK("#'Test Cases'!A"&(MATCH(A12,'Test Cases'!$B$5:$B$300,0)+4),"→ xem TC"),"") -> → xem TC
A13: F09 | B13: M3 – Trang chủ & Tìm kiếm | C13: Gợi ý tìm kiếm | D13: search_suggestions.php | E13: GET q | F13: Nhóm 1 | G13: =IFERROR(VLOOKUP(F13,'Cấu hình'!$F$7:$G$9,2,FALSE()),"") -> Lâm Hoài An | H13: =COUNTIF('Test Cases'!$B$5:$B$300,A13) -> 2 | I13: =H13-COUNTIFS('Test Cases'!$B$5:$B$300,A13,'Test Cases'!$T$5:$T$300,"Not Run") -> 0 | J13: =COUNTIFS('Test Cases'!$B$5:$B$300,A13,'Test Cases'!$T$5:$T$300,"Pass") -> 0 | K13: =COUNTIFS('Test Cases'!$B$5:$B$300,A13,'Test Cases'!$T$5:$T$300,"Fail") -> 0 | L13: =IF(H13=0,0,I13/H13) -> 0 | M13: =IF(H13=0,"CHƯA CÓ TC","Đã cover") -> Đã cover | N13: =IFERROR(HYPERLINK("#'Test Cases'!A"&(MATCH(A13,'Test Cases'!$B$5:$B$300,0)+4),"→ xem TC"),"") -> → xem TC
A14: F10 | B14: M3 – Trang chủ & Tìm kiếm | C14: Trang giới thiệu | D14: pages/about.php | E14: GET | F14: Nhóm 1 | G14: =IFERROR(VLOOKUP(F14,'Cấu hình'!$F$7:$G$9,2,FALSE()),"") -> Lâm Hoài An | H14: =COUNTIF('Test Cases'!$B$5:$B$300,A14) -> 1 | I14: =H14-COUNTIFS('Test Cases'!$B$5:$B$300,A14,'Test Cases'!$T$5:$T$300,"Not Run") -> 0 | J14: =COUNTIFS('Test Cases'!$B$5:$B$300,A14,'Test Cases'!$T$5:$T$300,"Pass") -> 0 | K14: =COUNTIFS('Test Cases'!$B$5:$B$300,A14,'Test Cases'!$T$5:$T$300,"Fail") -> 0 | L14: =IF(H14=0,0,I14/H14) -> 0 | M14: =IF(H14=0,"CHƯA CÓ TC","Đã cover") -> Đã cover | N14: =IFERROR(HYPERLINK("#'Test Cases'!A"&(MATCH(A14,'Test Cases'!$B$5:$B$300,0)+4),"→ xem TC"),"") -> → xem TC
A15: F11 | B15: M4 – Gallery & Bot | C15: Danh sách Gallery / lọc | D15: pages/gallery.php | E15: GET | F15: Nhóm 1 | G15: =IFERROR(VLOOKUP(F15,'Cấu hình'!$F$7:$G$9,2,FALSE()),"") -> Lâm Hoài An | H15: =COUNTIF('Test Cases'!$B$5:$B$300,A15) -> 2 | I15: =H15-COUNTIFS('Test Cases'!$B$5:$B$300,A15,'Test Cases'!$T$5:$T$300,"Not Run") -> 0 | J15: =COUNTIFS('Test Cases'!$B$5:$B$300,A15,'Test Cases'!$T$5:$T$300,"Pass") -> 0 | K15: =COUNTIFS('Test Cases'!$B$5:$B$300,A15,'Test Cases'!$T$5:$T$300,"Fail") -> 0 | L15: =IF(H15=0,0,I15/H15) -> 0 | M15: =IF(H15=0,"CHƯA CÓ TC","Đã cover") -> Đã cover | N15: =IFERROR(HYPERLINK("#'Test Cases'!A"&(MATCH(A15,'Test Cases'!$B$5:$B$300,0)+4),"→ xem TC"),"") -> → xem TC
A16: F12 | B16: M4 – Gallery & Bot | C16: Chi tiết nhóm ảnh | D16: pages/group_detail.php | E16: GET id | F16: Nhóm 1 | G16: =IFERROR(VLOOKUP(F16,'Cấu hình'!$F$7:$G$9,2,FALSE()),"") -> Lâm Hoài An | H16: =COUNTIF('Test Cases'!$B$5:$B$300,A16) -> 2 | I16: =H16-COUNTIFS('Test Cases'!$B$5:$B$300,A16,'Test Cases'!$T$5:$T$300,"Not Run") -> 0 | J16: =COUNTIFS('Test Cases'!$B$5:$B$300,A16,'Test Cases'!$T$5:$T$300,"Pass") -> 0 | K16: =COUNTIFS('Test Cases'!$B$5:$B$300,A16,'Test Cases'!$T$5:$T$300,"Fail") -> 0 | L16: =IF(H16=0,0,I16/H16) -> 0 | M16: =IF(H16=0,"CHƯA CÓ TC","Đã cover") -> Đã cover | N16: =IFERROR(HYPERLINK("#'Test Cases'!A"&(MATCH(A16,'Test Cases'!$B$5:$B$300,0)+4),"→ xem TC"),"") -> → xem TC
... A56: F52 | B56: M11 – Phi chức năng | C56: Cấu hình & quản lý phiên | D56: config/database.php | E56: Cookie, session, hiển thị lỗi | F56: Nhóm 2 | G56: =IFERROR(VLOOKUP(F56,'Cấu hình'!$F$7:$G$9,2,FALSE()),"") -> Nguyễn Phúc Khang | H56: =COUNTIF('Test Cases'!$B$5:$B$300,A56) -> 1 | I56: =H56-COUNTIFS('Test Cases'!$B$5:$B$300,A56,'Test Cases'!$T$5:$T$300,"Not Run") -> 0 | J56: =COUNTIFS('Test Cases'!$B$5:$B$300,A56,'Test Cases'!$T$5:$T$300,"Pass") -> 0 | K56: =COUNTIFS('Test Cases'!$B$5:$B$300,A56,'Test Cases'!$T$5:$T$300,"Fail") -> 0 | L56: =IF(H56=0,0,I56/H56) -> 0 | M56: =IF(H56=0,"CHƯA CÓ TC","Đã cover") -> Đã cover | N56: =IFERROR(HYPERLINK("#'Test Cases'!A"&(MATCH(A56,'Test Cases'!$B$5:$B$300,0)+4),"→ xem TC"),"") -> → xem TC
C57: TỔNG | H57: =SUM(H5:H56) -> 100 | I57: =SUM(I5:I56) -> 0 | J57: =SUM(J5:J56) -> 0 | K57: =SUM(K5:K56) -> 0 | L57: =IF(H57=0,0,I57/H57) -> 0 | M57: =IF(COUNTIF(M5:M56,"CHƯA CÓ TC")=0,"Cover đủ "&COUNTA(A5:A56)&" CN","Còn sót "&COUNTIF(M5:M56,"CHƯA CÓ TC")&" CN") -> Cover đủ 52 CN

Sheet Test Scenario
A1: Test Scenario – ANYN
A2: 12 kịch bản nghiệp vụ. Số TC và kết quả tự tính từ Test Cases.
A4: SC ID | B4: Tên kịch bản | C4: Mô tả luồng | D4: Chức năng liên quan | E4: Vai trò tham gia | F4: Ưu tiên | G4: Số TC | H4: Đã chạy | I4: Pass | J4: Fail
A5: SC01 | B5: Đăng ký, đăng nhập, quên mật khẩu và quản lý phiên | C5: Người dùng đăng ký, đăng nhập, bị khóa khi sai nhiều lần, đặt lại mật khẩu, đăng xuất | D5: F01-F06 | E5: Guest, User | F5: P1 | G5: =COUNTIF('Test Cases'!$E$5:$E$300,A5) -> 12 | H5: =G5-COUNTIFS('Test Cases'!$E$5:$E$300,A5,'Test Cases'!$T$5:$T$300,"Not Run") -> 0 | I5: =COUNTIFS('Test Cases'!$E$5:$E$300,A5,'Test Cases'!$T$5:$T$300,"Pass") -> 0 | J5: =COUNTIFS('Test Cases'!$E$5:$E$300,A5,'Test Cases'!$T$5:$T$300,"Fail") -> 0
A6: SC02 | B6: Phân quyền truy cập Guest / User / Admin | C6: Truy cập trực tiếp bằng URL vào các trang cần đăng nhập và trang quản trị với từng vai trò | D6: F07 | E6: Guest, User, Admin | F6: P1 | G6: =COUNTIF('Test Cases'!$E$5:$E$300,A6) -> 4 | H6: =G6-COUNTIFS('Test Cases'!$E$5:$E$300,A6,'Test Cases'!$T$5:$T$300,"Not Run") -> 0 | I6: =COUNTIFS('Test Cases'!$E$5:$E$300,A6,'Test Cases'!$T$5:$T$300,"Pass") -> 0 | J6: =COUNTIFS('Test Cases'!$E$5:$E$300,A6,'Test Cases'!$T$5:$T$300,"Fail") -> 0
A7: SC03 | B7: Duyệt gallery, tìm kiếm và xem chi tiết bot | C7: Mở trang chủ, tìm kiếm, lọc gallery, xem nhóm ảnh, xem bot, thả tim ảnh | D7: F08-F13, F17 | E7: Guest, User | F7: P1 | G7: =COUNTIF('Test Cases'!$E$5:$E$300,A7) -> 12 | H7: =G7-COUNTIFS('Test Cases'!$E$5:$E$300,A7,'Test Cases'!$T$5:$T$300,"Not Run") -> 0 | I7: =COUNTIFS('Test Cases'!$E$5:$E$300,A7,'Test Cases'!$T$5:$T$300,"Pass") -> 0 | J7: =COUNTIFS('Test Cases'!$E$5:$E$300,A7,'Test Cases'!$T$5:$T$300,"Fail") -> 0
A8: SC04 | B8: Đánh giá và bình luận bot | C8: Chấm điểm, thêm, sửa, xóa bình luận; thao tác trên dữ liệu của người khác | D8: F14-F16 | E8: User | F8: P1 | G8: =COUNTIF('Test Cases'!$E$5:$E$300,A8) -> 7 | H8: =G8-COUNTIFS('Test Cases'!$E$5:$E$300,A8,'Test Cases'!$T$5:$T$300,"Not Run") -> 0 | I8: =COUNTIFS('Test Cases'!$E$5:$E$300,A8,'Test Cases'!$T$5:$T$300,"Pass") -> 0 | J8: =COUNTIFS('Test Cases'!$E$5:$E$300,A8,'Test Cases'!$T$5:$T$300,"Fail") -> 0
A9: SC05 | B9: Vòng đời ý tưởng (Idea) | C9: Gửi, sửa, xóa, upvote idea; admin chuyển open → in_progress → completed → reopen | D9: F18-F23 | E9: User, Admin | F9: P1 | G9: =COUNTIF('Test Cases'!$E$5:$E$300,A9) -> 13 | H9: =G9-COUNTIFS('Test Cases'!$E$5:$E$300,A9,'Test Cases'!$T$5:$T$300,"Not Run") -> 0 | I9: =COUNTIFS('Test Cases'!$E$5:$E$300,A9,'Test Cases'!$T$5:$T$300,"Pass") -> 0 | J9: =COUNTIFS('Test Cases'!$E$5:$E$300,A9,'Test Cases'!$T$5:$T$300,"Fail") -> 0
A10: SC06 | B10: Đặt Commission và dùng voucher | C10: Tạo yêu cầu, dùng voucher, upload ảnh minh họa, xác nhận thanh toán, xem danh sách của tôi | D10: F24-F28 | E10: User | F10: P1 | G10: =COUNTIF('Test Cases'!$E$5:$E$300,A10) -> 10 | H10: =G10-COUNTIFS('Test Cases'!$E$5:$E$300,A10,'Test Cases'!$T$5:$T$300,"Not Run") -> 0 | I10: =COUNTIFS('Test Cases'!$E$5:$E$300,A10,'Test Cases'!$T$5:$T$300,"Pass") -> 0 | J10: =COUNTIFS('Test Cases'!$E$5:$E$300,A10,'Test Cases'!$T$5:$T$300,"Fail") -> 0
A11: SC07 | B11: Kinh tế gem: điểm danh, nhiệm vụ, mua đồ, giới hạn voucher | C11: Điểm danh, nhận gem theo nhiệm vụ, mua vật phẩm, trang bị khung, mua image set | D11: F29-F34 | E11: User | F11: P1 | G11: =COUNTIF('Test Cases'!$E$5:$E$300,A11) -> 13 | H11: =G11-COUNTIFS('Test Cases'!$E$5:$E$300,A11,'Test Cases'!$T$5:$T$300,"Not Run") -> 0 | I11: =COUNTIFS('Test Cases'!$E$5:$E$300,A11,'Test Cases'!$T$5:$T$300,"Pass") -> 0 | J11: =COUNTIFS('Test Cases'!$E$5:$E$300,A11,'Test Cases'!$T$5:$T$300,"Fail") -> 0
A12: SC08 | B12: Community gallery: upload, duyệt, reaction | C12: User upload ảnh, admin duyệt/từ chối, người dùng xem và thả reaction | D12: F35-F38 | E12: User, Admin | F12: P1 | G12: =COUNTIF('Test Cases'!$E$5:$E$300,A12) -> 9 | H12: =G12-COUNTIFS('Test Cases'!$E$5:$E$300,A12,'Test Cases'!$T$5:$T$300,"Not Run") -> 0 | I12: =COUNTIFS('Test Cases'!$E$5:$E$300,A12,'Test Cases'!$T$5:$T$300,"Pass") -> 0 | J12: =COUNTIFS('Test Cases'!$E$5:$E$300,A12,'Test Cases'!$T$5:$T$300,"Fail") -> 0
A13: SC09 | B13: Hồ sơ cá nhân và follow | C13: Xem/sửa bio, avatar; xem trang người khác; follow, unfollow | D13: F39-F40 | E13: User | F13: P2 | G13: =COUNTIF('Test Cases'!$E$5:$E$300,A13) -> 2 | H13: =G13-COUNTIFS('Test Cases'!$E$5:$E$300,A13,'Test Cases'!$T$5:$T$300,"Not Run") -> 0 | I13: =COUNTIFS('Test Cases'!$E$5:$E$300,A13,'Test Cases'!$T$5:$T$300,"Pass") -> 0 | J13: =COUNTIFS('Test Cases'!$E$5:$E$300,A13,'Test Cases'!$T$5:$T$300,"Fail") -> 0
A14: SC10 | B14: Quản trị nội dung | C14: Admin thêm/sửa/xóa bot, quản lý nhóm ảnh, xem thống kê | D14: F41-F44 | E14: Admin | F14: P2 | G14: =COUNTIF('Test Cases'!$E$5:$E$300,A14) -> 4 | H14: =G14-COUNTIFS('Test Cases'!$E$5:$E$300,A14,'Test Cases'!$T$5:$T$300,"Not Run") -> 0 | I14: =COUNTIFS('Test Cases'!$E$5:$E$300,A14,'Test Cases'!$T$5:$T$300,"Pass") -> 0 | J14: =COUNTIFS('Test Cases'!$E$5:$E$300,A14,'Test Cases'!$T$5:$T$300,"Fail") -> 0
A15: SC11 | B15: Bảo mật ứng dụng | C15: CSRF, XSS, SQL injection, upload tệp, bộ lọc nội dung, cấu hình và phiên | D15: F45-F49, F52 | E15: Mọi vai trò | F15: P1 | G15: =COUNTIF('Test Cases'!$E$5:$E$300,A15) -> 12 | H15: =G15-COUNTIFS('Test Cases'!$E$5:$E$300,A15,'Test Cases'!$T$5:$T$300,"Not Run") -> 0 | I15: =COUNTIFS('Test Cases'!$E$5:$E$300,A15,'Test Cases'!$T$5:$T$300,"Pass") -> 0 | J15: =COUNTIFS('Test Cases'!$E$5:$E$300,A15,'Test Cases'!$T$5:$T$300,"Fail") -> 0
A16: SC12 | B16: Giao diện, tương thích và hiệu năng cơ bản | C16: Chạy luồng chính trên Chrome/Firefox/Edge, desktop và điện thoại, đo thời gian tải | D16: F50-F51 | E16: Mọi vai trò | F16: P2 | G16: =COUNTIF('Test Cases'!$E$5:$E$300,A16) -> 2 | H16: =G16-COUNTIFS('Test Cases'!$E$5:$E$300,A16,'Test Cases'!$T$5:$T$300,"Not Run") -> 0 | I16: =COUNTIFS('Test Cases'!$E$5:$E$300,A16,'Test Cases'!$T$5:$T$300,"Pass") -> 0 | J16: =COUNTIFS('Test Cases'!$E$5:$E$300,A16,'Test Cases'!$T$5:$T$300,"Fail") -> 0
B17: TỔNG | G17: =SUM(G5:G16) -> 100 | H17: =SUM(H5:H16) -> 0 | I17: =SUM(I5:I16) -> 0 | J17: =SUM(J5:J16) -> 0

Sheet Test Cases
A1: Test Cases – ANYN
A2: Nhập: cột vàng. Cột xanh lá tự điền. Lọc cột G theo tên bạn để chỉ thấy TC của mình.
A4: TC ID | B4: Mã CN | C4: Module | D4: Chức năng | E4: Scenario | F4: Nhóm (tự động) | G4: Người phụ trách (tự động) | H4: Tiêu đề test case | I4: Điều kiện tiên quyết | J4: Các bước thực hiện | K4: Dữ liệu test | L4: Kết quả mong đợi | M4: Kỹ thuật thiết kế | N4: Loại test | O4: Ưu tiên | P4: Tự động hóa | Q4: Người thực hiện | R4: Ngày test | S4: Kết quả thực tế | T4: Trạng thái | U4: Bug ID | V4: Ghi chú | W4: Cảnh báo (tự động)
A5: TC001 | B5: F01 | C5: M1 – Tài khoản | D5: Đăng ký tài khoản | E5: SC01 | F5: =IFERROR(INDEX('Checklist cover'!$F$5:$F$56,MATCH(B5,'Checklist cover'!$A$5:$A$56,0)),"") -> Nhóm 1 | G5: =IFERROR(VLOOKUP(F5,'Cấu hình'!$F$7:$G$9,2,FALSE()),"") -> Lâm Hoài An | H5: Đăng ký thành công với dữ liệu hợp lệ | I5: Chưa đăng nhập | J5: 1. Mở trang Đăng ký 2. Nhập username, email, mật khẩu hợp lệ 3. Bấm Đăng ký | K5: user: tester01 / tester01@mail.com / Test1234 | L5: Tạo tài khoản, chuyển sang đăng nhập hoặc vào trang chủ; role = user; DB có 1 bản ghi mới | M5: Use Case (luồng nghiệp vụ) | N5: Chức năng | O5: P1 | Q5: =IF(T5="Not Run","",G5) | T5: Not Run | W5: =IF(AND(T5="Fail",U5=""),"⚠ Fail nhưng thiếu Bug ID",IF(AND(T5<>"Not Run",T5<>"",R5=""),"⚠ Thiếu ngày test",IF(AND(T5="Pass",S5=""),"⚠ Thiếu kết quả thực tế","")))
A6: TC002 | B6: F01 | C6: M1 – Tài khoản | D6: Đăng ký tài khoản | E6: SC01 | F6: =IFERROR(INDEX('Checklist cover'!$F$5:$F$56,MATCH(B6,'Checklist cover'!$A$5:$A$56,0)),"") -> Nhóm 1 | G6: =IFERROR(VLOOKUP(F6,'Cấu hình'!$F$7:$G$9,2,FALSE()),"") -> Lâm Hoài An | H6: Đăng ký trùng email | I6: Đã có tài khoản tester01@mail.com | J6: Đăng ký lại với email đã tồn tại, username khác | K6: email trùng | L6: Báo lỗi email đã tồn tại, không tạo tài khoản mới | M6: Equivalence Partitioning | N6: Chức năng | O6: P1 | Q6: =IF(T6="Not Run","",G6) | T6: Not Run | W6: =IF(AND(T6="Fail",U6=""),"⚠ Fail nhưng thiếu Bug ID",IF(AND(T6<>"Not Run",T6<>"",R6=""),"⚠ Thiếu ngày test",IF(AND(T6="Pass",S6=""),"⚠ Thiếu kết quả thực tế","")))
A7: TC003 | B7: F01 | C7: M1 – Tài khoản | D7: Đăng ký tài khoản | E7: SC01 | F7: =IFERROR(INDEX('Checklist cover'!$F$5:$F$56,MATCH(B7,'Checklist cover'!$A$5:$A$56,0)),"") -> Nhóm 1 | G7: =IFERROR(VLOOKUP(F7,'Cấu hình'!$F$7:$G$9,2,FALSE()),"") -> Lâm Hoài An | H7: Mật khẩu ngắn hơn 8 ký tự | J7: Nhập mật khẩu 7 ký tự | K7: Abc1234 | L7: Báo lỗi 'at least 8 characters' | M7: Boundary Value Analysis | N7: Biên | O7: P1 | Q7: =IF(T7="Not Run","",G7) | T7: Not Run | W7: =IF(AND(T7="Fail",U7=""),"⚠ Fail nhưng thiếu Bug ID",IF(AND(T7<>"Not Run",T7<>"",R7=""),"⚠ Thiếu ngày test",IF(AND(T7="Pass",S7=""),"⚠ Thiếu kết quả thực tế","")))
A8: TC004 | B8: F02 | C8: M1 – Tài khoản | D8: Đăng nhập | E8: SC01 | F8: =IFERROR(INDEX('Checklist cover'!$F$5:$F$56,MATCH(B8,'Checklist cover'!$A$5:$A$56,0)),"") -> Nhóm 1 | G8: =IFERROR(VLOOKUP(F8,'Cấu hình'!$F$7:$G$9,2,FALSE()),"") -> Lâm Hoài An | H8: Đăng nhập đúng | I8: Có tài khoản user | J8: Nhập email + mật khẩu đúng | K8: tester01 | L8: Đăng nhập thành công, header hiện tên/menu người dùng | M8: Use Case (luồng nghiệp vụ) | N8: Chức năng | O8: P1 | P8: AT01 | Q8: =IF(T8="Not Run","",G8) | T8: Not Run | W8: =IF(AND(T8="Fail",U8=""),"⚠ Fail nhưng thiếu Bug ID",IF(AND(T8<>"Not Run",T8<>"",R8=""),"⚠ Thiếu ngày test",IF(AND(T8="Pass",S8=""),"⚠ Thiếu kết quả thực tế","")))
A9: TC005 | B9: F02 | C9: M1 – Tài khoản | D9: Đăng nhập | E9: SC01 | F9: =IFERROR(INDEX('Checklist cover'!$F$5:$F$56,MATCH(B9,'Checklist cover'!$A$5:$A$56,0)),"") -> Nhóm 1 | G9: =IFERROR(VLOOKUP(F9,'Cấu hình'!$F$7:$G$9,2,FALSE()),"") -> Lâm Hoài An | H9: Đăng nhập sai mật khẩu | I9: Có tài khoản user | J9: Nhập email đúng, mật khẩu sai | K9: sai mật khẩu | L9: Báo lỗi chung, không đăng nhập; không tiết lộ email có tồn tại | M9: Equivalence Partitioning | N9: Chức năng | O9: P1 | Q9: =IF(T9="Not Run","",G9) | T9: Not Run | W9: =IF(AND(T9="Fail",U9=""),"⚠ Fail nhưng thiếu Bug ID",IF(AND(T9<>"Not Run",T9<>"",R9=""),"⚠ Thiếu ngày test",IF(AND(T9="Pass",S9=""),"⚠ Thiếu kết quả thực tế","")))
A10: TC006 | B10: F03 | C10: M1 – Tài khoản | D10: Chống dò mật khẩu (throttle) | E10: SC01 | F10: =IFERROR(INDEX('Checklist cover'!$F$5:$F$56,MATCH(B10,'Checklist cover'!$A$5:$A$56,0)),"") -> Nhóm 1 | G10: =IFERROR(VLOOKUP(F10,'Cấu hình'!$F$7:$G$9,2,FALSE()),"") -> Lâm Hoài An | H10: Sai 5 lần liên tiếp cùng email | I10: Có tài khoản user | J10: Đăng nhập sai mật khẩu 5 lần, lần 6 nhập đúng | K10: 15 phút | L10: Lần 6 bị chặn, có thông báo bị khóa tạm thời | M10: State Transition | N10: Bảo mật | O10: P1 | P10: AT02 | Q10: =IF(T10="Not Run","",G10) | T10: Not Run | W10: =IF(AND(T10="Fail",U10=""),"⚠ Fail nhưng thiếu Bug ID",IF(AND(T10<>"Not Run",T10<>"",R10=""),"⚠ Thiếu ngày test",IF(AND(T10="Pass",S10=""),"⚠ Thiếu kết quả thực tế","")))
A11: TC007 | B11: F03 | C11: M1 – Tài khoản | D11: Chống dò mật khẩu (throttle) | E11: SC01 | F11: =IFERROR(INDEX('Checklist cover'!$F$5:$F$56,MATCH(B11,'Checklist cover'!$A$5:$A$56,0)),"") -> Nhóm 1 | G11: =IFERROR(VLOOKUP(F11,'Cấu hình'!$F$7:$G$9,2,FALSE()),"") -> Lâm Hoài An | H11: Hết thời gian khóa | I11: Đang bị khóa | J11: Chờ qua 15 phút (hoặc sửa bản ghi login_attempts) rồi đăng nhập | L11: Đăng nhập lại được | M11: State Transition | N11: Chức năng | O11: P3 | Q11: =IF(T11="Not Run","",G11) | T11: Not Run | W11: =IF(AND(T11="Fail",U11=""),"⚠ Fail nhưng thiếu Bug ID",IF(AND(T11<>"Not Run",T11<>"",R11=""),"⚠ Thiếu ngày test",IF(AND(T11="Pass",S11=""),"⚠ Thiếu kết quả thực tế","")))
A12: TC008 | B12: F04 | C12: M1 – Tài khoản | D12: Đăng xuất | E12: SC01 | F12: =IFERROR(INDEX('Checklist cover'!$F$5:$F$56,MATCH(B12,'Checklist cover'!$A$5:$A$56,0)),"") -> Nhóm 1 | G12: =IFERROR(VLOOKUP(F12,'Cấu hình'!$F$7:$G$9,2,FALSE()),"") -> Lâm Hoài An | H12: Đăng xuất | I12: Đã đăng nhập | J12: Bấm Đăng xuất, sau đó nhấn nút Back của trình duyệt | L12: Session bị hủy; Back không vào lại được trang cần đăng nhập | M12: Use Case (luồng nghiệp vụ) | N12: Chức năng | O12: P1 | Q12: =IF(T12="Not Run","",G12) | T12: Not Run | W12: =IF(AND(T12="Fail",U12=""),"⚠ Fail nhưng thiếu Bug ID",IF(AND(T12<>"Not Run",T12<>"",R12=""),"⚠ Thiếu ngày test",IF(AND(T12="Pass",S12=""),"⚠ Thiếu kết quả thực tế","")))
A13: TC009 | B13: F05 | C13: M1 – Tài khoản | D13: Quên mật khẩu | E13: SC01 | F13: =IFERROR(INDEX('Checklist cover'!$F$5:$F$56,MATCH(B13,'Checklist cover'!$A$5:$A$56,0)),"") -> Nhóm 1 | G13: =IFERROR(VLOOKUP(F13,'Cấu hình'!$F$7:$G$9,2,FALSE()),"") -> Lâm Hoài An | H13: Yêu cầu reset với email tồn tại | I13: Có tài khoản | J13: Nhập email đúng ở trang Quên mật khẩu | K13: email hợp lệ | L13: Có thông báo đã gửi (hoặc hiện link reset khi APP_ENV=development) | M13: Use Case (luồng nghiệp vụ) | N13: Chức năng | O13: P1 | Q13: =IF(T13="Not Run","",G13) | T13: Not Run | W13: =IF(AND(T13="Fail",U13=""),"⚠ Fail nhưng thiếu Bug ID",IF(AND(T13<>"Not Run",T13<>"",R13=""),"⚠ Thiếu ngày test",IF(AND(T13="Pass",S13=""),"⚠ Thiếu kết quả thực tế","")))
A14: TC010 | B14: F05 | C14: M1 – Tài khoản | D14: Quên mật khẩu | E14: SC01 | F14: =IFERROR(INDEX('Checklist cover'!$F$5:$F$56,MATCH(B14,'Checklist cover'!$A$5:$A$56,0)),"") -> Nhóm 1 | G14: =IFERROR(VLOOKUP(F14,'Cấu hình'!$F$7:$G$9,2,FALSE()),"") -> Lâm Hoài An | H14: Yêu cầu reset với email không tồn tại | J14: Nhập email chưa đăng ký | K14: none@mail.com | L14: Thông báo trung tính, không lộ email có tồn tại hay không | M14: Experience-based (Error Guessing) | N14: Bảo mật | O14: P2 | Q14: =IF(T14="Not Run","",G14) | T14: Not Run | W14: =IF(AND(T14="Fail",U14=""),"⚠ Fail nhưng thiếu Bug ID",IF(AND(T14<>"Not Run",T14<>"",R14=""),"⚠ Thiếu ngày test",IF(AND(T14="Pass",S14=""),"⚠ Thiếu kết quả thực tế","")))
A15: TC011 | B15: F06 | C15: M1 – Tài khoản | D15: Đặt lại mật khẩu bằng token | E15: SC01 | F15: =IFERROR(INDEX('Checklist cover'!$F$5:$F$56,MATCH(B15,'Checklist cover'!$A$5:$A$56,0)),"") -> Nhóm 1 | G15: =IFERROR(VLOOKUP(F15,'Cấu hình'!$F$7:$G$9,2,FALSE()),"") -> Lâm Hoài An | H15: Reset bằng token hợp lệ | I15: Có link reset | J15: Mở link, nhập mật khẩu mới hợp lệ | K15: Newpass123 | L15: Đổi mật khẩu thành công, đăng nhập được bằng mật khẩu mới | M15: State Transition | N15: Chức năng | O15: P1 | Q15: =IF(T15="Not Run","",G15) | T15: Not Run | W15: =IF(AND(T15="Fail",U15=""),"⚠ Fail nhưng thiếu Bug ID",IF(AND(T15<>"Not Run",T15<>"",R15=""),"⚠ Thiếu ngày test",IF(AND(T15="Pass",S15=""),"⚠ Thiếu kết quả thực tế","")))
A16: TC012 | B16: F06 | C16: M1 – Tài khoản | D16: Đặt lại mật khẩu bằng token | E16: SC01 | F16: =IFERROR(INDEX('Checklist cover'!$F$5:$F$56,MATCH(B16,'Checklist cover'!$A$5:$A$56,0)),"") -> Nhóm 1 | G16: =IFERROR(VLOOKUP(F16,'Cấu hình'!$F$7:$G$9,2,FALSE()),"") -> Lâm Hoài An | H16: Dùng lại token đã sử dụng | I16: Token đã dùng | J16: Mở lại link reset cũ | L16: Báo token không hợp lệ/đã dùng | M16: State Transition | N16: Bảo mật | O16: P1 | Q16: =IF(T16="Not Run","",G16) | T16: Not Run | W16: =IF(AND(T16="Fail",U16=""),"⚠ Fail nhưng thiếu Bug ID",IF(AND(T16<>"Not Run",T16<>"",R16=""),"⚠ Thiếu ngày test",IF(AND(T16="Pass",S16=""),"⚠ Thiếu kết quả thực tế","")))
A17: TC013 | B17: F07 | C17: M2 – Phân quyền | D17: Truy cập theo vai trò Guest/User/Admin | E17: SC02 | F17: =IFERROR(INDEX('Checklist cover'!$F$5:$F$56,MATCH(B17,'Checklist cover'!$A$5:$A$56,0)),"") -> Nhóm 1 | G17: =IFERROR(VLOOKUP(F17,'Cấu hình'!$F$7:$G$9,2,FALSE()),"") -> Lâm Hoài An | H17: Guest vào trang cần đăng nhập | I17: Chưa đăng nhập | J17: Mở trực tiếp profile.php, commission.php, shop.php, my_commissions.php, submit_idea.php | K17: URL trực tiếp | L17: Chuyển hướng về trang đăng nhập | M17: Decision Table | N17: Phân quyền | O17: P1 | Q17: =IF(T17="Not Run","",G17) | T17: Not Run | W17: =IF(AND(T17="Fail",U17=""),"⚠ Fail nhưng thiếu Bug ID",IF(AND(T17<>"Not Run",T17<>"",R17=""),"⚠ Thiếu ngày test",IF(AND(T17="Pass",S17=""),"⚠ Thiếu kết quả thực tế","")))
A18: TC014 | B18: F07 | C18: M2 – Phân quyền | D18: Truy cập theo vai trò Guest/User/Admin | E18: SC02 | F18: =IFERROR(INDEX('Checklist cover'!$F$5:$F$56,MATCH(B18,'Checklist cover'!$A$5:$A$56,0)),"") -> Nhóm 1 | G18: =IFERROR(VLOOKUP(F18,'Cấu hình'!$F$7:$G$9,2,FALSE()),"") -> Lâm Hoài An | H18: Guest vào trang Admin | I18: Chưa đăng nhập | J18: Mở admin_bots.php, admin_stats.php, admin_community.php, admin_groups.php, admin_add_bot.php | K18: URL trực tiếp | L18: Bị chặn (403 hoặc chuyển hướng), không lộ dữ liệu | M18: Decision Table | N18: Phân quyền | O18: P1 | P18: AT03 | Q18: =IF(T18="Not Run","",G18) | T18: Not Run | W18: =IF(AND(T18="Fail",U18=""),"⚠ Fail nhưng thiếu Bug ID",IF(AND(T18<>"Not Run",T18<>"",R18=""),"⚠ Thiếu ngày test",IF(AND(T18="Pass",S18=""),"⚠ Thiếu kết quả thực tế","")))
A19: TC015 | B19: F07 | C19: M2 – Phân quyền | D19: Truy cập theo vai trò Guest/User/Admin | E19: SC02 | F19: =IFERROR(INDEX('Checklist cover'!$F$5:$F$56,MATCH(B19,'Checklist cover'!$A$5:$A$56,0)),"") -> Nhóm 1 | G19: =IFERROR(VLOOKUP(F19,'Cấu hình'!$F$7:$G$9,2,FALSE()),"") -> Lâm Hoài An | H19: User thường vào trang Admin | I19: Đăng nhập user | J19: Mở từng trang admin_* bằng URL | K19: URL trực tiếp | L19: Hiện 'Access Denied', mã 403 | M19: Decision Table | N19: Phân quyền | O19: P1 | Q19: =IF(T19="Not Run","",G19) | T19: Not Run | W19: =IF(AND(T19="Fail",U19=""),"⚠ Fail nhưng thiếu Bug ID",IF(AND(T19<>"Not Run",T19<>"",R19=""),"⚠ Thiếu ngày test",IF(AND(T19="Pass",S19=""),"⚠ Thiếu kết quả thực tế","")))
A20: TC016 | B20: F07 | C20: M2 – Phân quyền | D20: Truy cập theo vai trò Guest/User/Admin | E20: SC02 | F20: =IFERROR(INDEX('Checklist cover'!$F$5:$F$56,MATCH(B20,'Checklist cover'!$A$5:$A$56,0)),"") -> Nhóm 1 | G20: =IFERROR(VLOOKUP(F20,'Cấu hình'!$F$7:$G$9,2,FALSE()),"") -> Lâm Hoài An | H20: Admin truy cập đầy đủ | I20: Đăng nhập admin | J20: Mở tất cả trang admin_* | L20: Truy cập bình thường | M20: Decision Table | N20: Phân quyền | O20: P1 | Q20: =IF(T20="Not Run","",G20) | T20: Not Run | W20: =IF(AND(T20="Fail",U20=""),"⚠ Fail nhưng thiếu Bug ID",IF(AND(T20<>"Not Run",T20<>"",R20=""),"⚠ Thiếu ngày test",IF(AND(T20="Pass",S20=""),"⚠ Thiếu kết quả thực tế","")))
A21: TC017 | B21: F08 | C21: M3 – Trang chủ & Tìm kiếm | D21: Trang chủ | E21: SC03 | F21: =IFERROR(INDEX('Checklist cover'!$F$5:$F$56,MATCH(B21,'Checklist cover'!$A$5:$A$56,0)),"") -> Nhóm 1 | G21: =IFERROR(VLOOKUP(F21,'Cấu hình'!$F$7:$G$9,2,FALSE()),"") -> Lâm Hoài An | H21: Trang chủ hiển thị đầy đủ | J21: Mở index.php | L21: Banner, menu, nội dung nổi bật tải đủ, không lỗi PHP/ảnh vỡ | M21: Experience-based (Error Guessing) | N21: Giao diện | O21: P1 | Q21: =IF(T21="Not Run","",G21) | T21: Not Run | W21: =IF(AND(T21="Fail",U21=""),"⚠ Fail nhưng thiếu Bug ID",IF(AND(T21<>"Not Run",T21<>"",R21=""),"⚠ Thiếu ngày test",IF(AND(T21="Pass",S21=""),"⚠ Thiếu kết quả thực tế","")))
A22: TC018 | B22: F08 | C22: M3 – Trang chủ & Tìm kiếm | D22: Trang chủ | E22: SC03 | F22: =IFERROR(INDEX('Checklist cover'!$F$5:$F$56,MATCH(B22,'Checklist cover'!$A$5:$A$56,0)),"") -> Nhóm 1 | G22: =IFERROR(VLOOKUP(F22,'Cấu hình'!$F$7:$G$9,2,FALSE()),"") -> Lâm Hoài An | H22: Điều hướng menu | J22: Bấm lần lượt các mục menu | L22: Mỗi mục dẫn đúng trang, không 404 | M22: Use Case (luồng nghiệp vụ) | N22: Chức năng | O22: P2 | Q22: =IF(T22="Not Run","",G22) | T22: Not Run | W22: =IF(AND(T22="Fail",U22=""),"⚠ Fail nhưng thiếu Bug ID",IF(AND(T22<>"Not Run",T22<>"",R22=""),"⚠ Thiếu ngày test",IF(AND(T22="Pass",S22=""),"⚠ Thiếu kết quả thực tế","")))
A23: TC019 | B23: F09 | C23: M3 – Trang chủ & Tìm kiếm | D23: Gợi ý tìm kiếm | E23: SC03 | F23: =IFERROR(INDEX('Checklist cover'!$F$5:$F$56,MATCH(B23,'Checklist cover'!$A$5:$A$56,0)),"") -> Nhóm 1 | G23: =IFERROR(VLOOKUP(F23,'Cấu hình'!$F$7:$G$9,2,FALSE()),"") -> Lâm Hoài An | H23: Gợi ý tìm kiếm có kết quả | J23: Gõ từ khóa có trong dữ liệu | K23: 1-3 ký tự đầu của tên bot | L23: Danh sách gợi ý hợp lý, định dạng đúng | M23: Use Case (luồng nghiệp vụ) | N23: Chức năng | O23: P2 | Q23: =IF(T23="Not Run","",G23) | T23: Not Run | W23: =IF(AND(T23="Fail",U23=""),"⚠ Fail nhưng thiếu Bug ID",IF(AND(T23<>"Not Run",T23<>"",R23=""),"⚠ Thiếu ngày test",IF(AND(T23="Pass",S23=""),"⚠ Thiếu kết quả thực tế","")))
A24: TC020 | B24: F09 | C24: M3 – Trang chủ & Tìm kiếm | D24: Gợi ý tìm kiếm | E24: SC03 | F24: =IFERROR(INDEX('Checklist cover'!$F$5:$F$56,MATCH(B24,'Checklist cover'!$A$5:$A$56,0)),"") -> Nhóm 1 | G24: =IFERROR(VLOOKUP(F24,'Cấu hình'!$F$7:$G$9,2,FALSE()),"") -> Lâm Hoài An | H24: Tìm kiếm không có kết quả | J24: Gõ từ khóa không tồn tại | K24: zzzzqq | L24: Trả về rỗng hoặc thông báo, không lỗi | M24: Use Case (luồng nghiệp vụ) | N24: Chức năng | O24: P3 | Q24: =IF(T24="Not Run","",G24) | T24: Not Run | W24: =IF(AND(T24="Fail",U24=""),"⚠ Fail nhưng thiếu Bug ID",IF(AND(T24<>"Not Run",T24<>"",R24=""),"⚠ Thiếu ngày test",IF(AND(T24="Pass",S24=""),"⚠ Thiếu kết quả thực tế","")))
A25: TC021 | B25: F10 | C25: M3 – Trang chủ & Tìm kiếm | D25: Trang giới thiệu | E25: SC03 | F25: =IFERROR(INDEX('Checklist cover'!$F$5:$F$56,MATCH(B25,'Checklist cover'!$A$5:$A$56,0)),"") -> Nhóm 1 | G25: =IFERROR(VLOOKUP(F25,'Cấu hình'!$F$7:$G$9,2,FALSE()),"") -> Lâm Hoài An | H25: Trang About | J25: Mở about.php | L25: Nội dung hiển thị đúng, link hoạt động | M25: Experience-based (Error Guessing) | N25: Giao diện | O25: P3 | Q25: =IF(T25="Not Run","",G25) | T25: Not Run | W25: =IF(AND(T25="Fail",U25=""),"⚠ Fail nhưng thiếu Bug ID",IF(AND(T25<>"Not Run",T25<>"",R25=""),"⚠ Thiếu ngày test",IF(AND(T25="Pass",S25=""),"⚠ Thiếu kết quả thực tế","")))
A26: TC022 | B26: F11 | C26: M4 – Gallery & Bot | D26: Danh sách Gallery / lọc | E26: SC03 | F26: =IFERROR(INDEX('Checklist cover'!$F$5:$F$56,MATCH(B26,'Checklist cover'!$A$5:$A$56,0)),"") -> Nhóm 1 | G26: =IFERROR(VLOOKUP(F26,'Cấu hình'!$F$7:$G$9,2,FALSE()),"") -> Lâm Hoài An | H26: Xem danh sách Gallery | J26: Mở gallery.php | L26: Ảnh tải đầy đủ, có phân nhóm | M26: Use Case (luồng nghiệp vụ) | N26: Chức năng | O26: P1 | Q26: =IF(T26="Not Run","",G26) | T26: Not Run | W26: =IF(AND(T26="Fail",U26=""),"⚠ Fail nhưng thiếu Bug ID",IF(AND(T26<>"Not Run",T26<>"",R26=""),"⚠ Thiếu ngày test",IF(AND(T26="Pass",S26=""),"⚠ Thiếu kết quả thực tế","")))
A27: TC023 | B27: F11 | C27: M4 – Gallery & Bot | D27: Danh sách Gallery / lọc | E27: SC03 | F27: =IFERROR(INDEX('Checklist cover'!$F$5:$F$56,MATCH(B27,'Checklist cover'!$A$5:$A$56,0)),"") -> Nhóm 1 | G27: =IFERROR(VLOOKUP(F27,'Cấu hình'!$F$7:$G$9,2,FALSE()),"") -> Lâm Hoài An | H27: Lọc/ phân trang Gallery | J27: Dùng bộ lọc và chuyển trang | L27: Kết quả đúng bộ lọc, không trùng/mất ảnh | M27: Use Case (luồng nghiệp vụ) | N27: Chức năng | O27: P2 | Q27: =IF(T27="Not Run","",G27) | T27: Not Run | W27: =IF(AND(T27="Fail",U27=""),"⚠ Fail nhưng thiếu Bug ID",IF(AND(T27<>"Not Run",T27<>"",R27=""),"⚠ Thiếu ngày test",IF(AND(T27="Pass",S27=""),"⚠ Thiếu kết quả thực tế","")))
A28: TC024 | B28: F12 | C28: M4 – Gallery & Bot | D28: Chi tiết nhóm ảnh | E28: SC03 | F28: =IFERROR(INDEX('Checklist cover'!$F$5:$F$56,MATCH(B28,'Checklist cover'!$A$5:$A$56,0)),"") -> Nhóm 1 | G28: =IFERROR(VLOOKUP(F28,'Cấu hình'!$F$7:$G$9,2,FALSE()),"") -> Lâm Hoài An | H28: Mở nhóm ảnh hợp lệ | J28: Bấm vào một nhóm | K28: id hợp lệ | L28: Hiển thị các ảnh thuộc nhóm | M28: Use Case (luồng nghiệp vụ) | N28: Chức năng | O28: P2 | Q28: =IF(T28="Not Run","",G28) | T28: Not Run | W28: =IF(AND(T28="Fail",U28=""),"⚠ Fail nhưng thiếu Bug ID",IF(AND(T28<>"Not Run",T28<>"",R28=""),"⚠ Thiếu ngày test",IF(AND(T28="Pass",S28=""),"⚠ Thiếu kết quả thực tế","")))
A29: TC025 | B29: F12 | C29: M4 – Gallery & Bot | D29: Chi tiết nhóm ảnh | E29: SC03 | F29: =IFERROR(INDEX('Checklist cover'!$F$5:$F$56,MATCH(B29,'Checklist cover'!$A$5:$A$56,0)),"") -> Nhóm 1 | G29: =IFERROR(VLOOKUP(F29,'Cấu hình'!$F$7:$G$9,2,FALSE()),"") -> Lâm Hoài An | H29: Nhóm ảnh id không tồn tại / không hợp lệ | J29: Mở group_detail.php?id=999999 và id=abc | K29: id lạ | L29: Thông báo không tìm thấy, không lỗi PHP/SQL | M29: Experience-based (Error Guessing) | N29: Bảo mật | O29: P2 | Q29: =IF(T29="Not Run","",G29) | T29: Not Run | W29: =IF(AND(T29="Fail",U29=""),"⚠ Fail nhưng thiếu Bug ID",IF(AND(T29<>"Not Run",T29<>"",R29=""),"⚠ Thiếu ngày test",IF(AND(T29="Pass",S29=""),"⚠ Thiếu kết quả thực tế","")))
A30: TC026 | B30: F13 | C30: M4 – Gallery & Bot | D30: Chi tiết Bot | E30: SC03 | F30: =IFERROR(INDEX('Checklist cover'!$F$5:$F$56,MATCH(B30,'Checklist cover'!$A$5:$A$56,0)),"") -> Nhóm 1 | G30: =IFERROR(VLOOKUP(F30,'Cấu hình'!$F$7:$G$9,2,FALSE()),"") -> Lâm Hoài An | H30: Xem chi tiết Bot | J30: Mở bot_detail.php?id=<hợp lệ> | L30: Hiển thị thông tin, tag, điểm, bình luận | M30: Use Case (luồng nghiệp vụ) | N30: Chức năng | O30: P1 | Q30: =IF(T30="Not Run","",G30) | T30: Not Run | W30: =IF(AND(T30="Fail",U30=""),"⚠ Fail nhưng thiếu Bug ID",IF(AND(T30<>"Not Run",T30<>"",R30=""),"⚠ Thiếu ngày test",IF(AND(T30="Pass",S30=""),"⚠ Thiếu kết quả thực tế","")))
A31: TC027 | B31: F13 | C31: M4 – Gallery & Bot | D31: Chi tiết Bot | E31: SC03 | F31: =IFERROR(INDEX('Checklist cover'!$F$5:$F$56,MATCH(B31,'Checklist cover'!$A$5:$A$56,0)),"") -> Nhóm 1 | G31: =IFERROR(VLOOKUP(F31,'Cấu hình'!$F$7:$G$9,2,FALSE()),"") -> Lâm Hoài An | H31: Bot id không tồn tại | J31: Mở id=999999 và id=' OR 1=1 | K31: id lạ | L31: Xử lý an toàn, không lộ lỗi SQL | M31: Experience-based (Error Guessing) | N31: Bảo mật | O31: P1 | Q31: =IF(T31="Not Run","",G31) | T31: Not Run | W31: =IF(AND(T31="Fail",U31=""),"⚠ Fail nhưng thiếu Bug ID",IF(AND(T31<>"Not Run",T31<>"",R31=""),"⚠ Thiếu ngày test",IF(AND(T31="Pass",S31=""),"⚠ Thiếu kết quả thực tế","")))
A32: TC028 | B32: F14 | C32: M4 – Gallery & Bot | D32: Chấm điểm Bot | E32: SC04 | F32: =IFERROR(INDEX('Checklist cover'!$F$5:$F$56,MATCH(B32,'Checklist cover'!$A$5:$A$56,0)),"") -> Nhóm 1 | G32: =IFERROR(VLOOKUP(F32,'Cấu hình'!$F$7:$G$9,2,FALSE()),"") -> Lâm Hoài An | H32: Chấm điểm hợp lệ | I32: Đăng nhập user | J32: Chọn điểm và gửi | K32: điểm 1..5 | L32: Điểm được lưu, điểm trung bình cập nhật | M32: Use Case (luồng nghiệp vụ) | N32: Chức năng | O32: P1 | Q32: =IF(T32="Not Run","",G32) | T32: Not Run | W32: =IF(AND(T32="Fail",U32=""),"⚠ Fail nhưng thiếu Bug ID",IF(AND(T32<>"Not Run",T32<>"",R32=""),"⚠ Thiếu ngày test",IF(AND(T32="Pass",S32=""),"⚠ Thiếu kết quả thực tế","")))
A33: TC029 | B33: F14 | C33: M4 – Gallery & Bot | D33: Chấm điểm Bot | E33: SC04 | F33: =IFERROR(INDEX('Checklist cover'!$F$5:$F$56,MATCH(B33,'Checklist cover'!$A$5:$A$56,0)),"") -> Nhóm 1 | G33: =IFERROR(VLOOKUP(F33,'Cấu hình'!$F$7:$G$9,2,FALSE()),"") -> Lâm Hoài An | H33: Chấm điểm ngoài khoảng cho phép | I33: Đăng nhập user | J33: Sửa giá trị score trong DevTools thành 0, 6, -1, 99, 'abc' | K33: score bất hợp lệ | L33: Bị từ chối, không lưu | M33: Boundary Value Analysis | N33: Biên | O33: P1 | Q33: =IF(T33="Not Run","",G33) | T33: Not Run | W33: =IF(AND(T33="Fail",U33=""),"⚠ Fail nhưng thiếu Bug ID",IF(AND(T33<>"Not Run",T33<>"",R33=""),"⚠ Thiếu ngày test",IF(AND(T33="Pass",S33=""),"⚠ Thiếu kết quả thực tế","")))
A34: TC030 | B34: F15 | C34: M4 – Gallery & Bot | D34: Thêm bình luận | E34: SC04 | F34: =IFERROR(INDEX('Checklist cover'!$F$5:$F$56,MATCH(B34,'Checklist cover'!$A$5:$A$56,0)),"") -> Nhóm 1 | G34: =IFERROR(VLOOKUP(F34,'Cấu hình'!$F$7:$G$9,2,FALSE()),"") -> Lâm Hoài An | H34: Thêm bình luận hợp lệ | I34: Đăng nhập user | J34: Nhập nội dung, gửi | K34: Bình luận 1 dòng | L34: Bình luận xuất hiện đúng người, đúng thời gian | M34: Use Case (luồng nghiệp vụ) | N34: Chức năng | O34: P1 | Q34: =IF(T34="Not Run","",G34) | T34: Not Run | W34: =IF(AND(T34="Fail",U34=""),"⚠ Fail nhưng thiếu Bug ID",IF(AND(T34<>"Not Run",T34<>"",R34=""),"⚠ Thiếu ngày test",IF(AND(T34="Pass",S34=""),"⚠ Thiếu kết quả thực tế","")))
A35: TC031 | B35: F15 | C35: M4 – Gallery & Bot | D35: Thêm bình luận | E35: SC04 | F35: =IFERROR(INDEX('Checklist cover'!$F$5:$F$56,MATCH(B35,'Checklist cover'!$A$5:$A$56,0)),"") -> Nhóm 1 | G35: =IFERROR(VLOOKUP(F35,'Cấu hình'!$F$7:$G$9,2,FALSE()),"") -> Lâm Hoài An | H35: Bình luận rỗng / chỉ khoảng trắng | I35: Đăng nhập user | J35: Gửi nội dung rỗng | K35: ' ' | L35: Bị từ chối | M35: Equivalence Partitioning | N35: Chức năng | O35: P2 | Q35: =IF(T35="Not Run","",G35) | T35: Not Run | W35: =IF(AND(T35="Fail",U35=""),"⚠ Fail nhưng thiếu Bug ID",IF(AND(T35<>"Not Run",T35<>"",R35=""),"⚠ Thiếu ngày test",IF(AND(T35="Pass",S35=""),"⚠ Thiếu kết quả thực tế","")))
A36: TC032 | B36: F16 | C36: M4 – Gallery & Bot | D36: Sửa / xóa bình luận | E36: SC04 | F36: =IFERROR(INDEX('Checklist cover'!$F$5:$F$56,MATCH(B36,'Checklist cover'!$A$5:$A$56,0)),"") -> Nhóm 1 | G36: =IFERROR(VLOOKUP(F36,'Cấu hình'!$F$7:$G$9,2,FALSE()),"") -> Lâm Hoài An | H36: Sửa bình luận của mình | I36: Có bình luận | J36: Sửa nội dung, lưu | L36: Nội dung cập nhật, hiện dấu 'đã sửa' (edited_at) | M36: Use Case (luồng nghiệp vụ) | N36: Chức năng | O36: P1 | Q36: =IF(T36="Not Run","",G36) | T36: Not Run | W36: =IF(AND(T36="Fail",U36=""),"⚠ Fail nhưng thiếu Bug ID",IF(AND(T36<>"Not Run",T36<>"",R36=""),"⚠ Thiếu ngày test",IF(AND(T36="Pass",S36=""),"⚠ Thiếu kết quả thực tế","")))
A37: TC033 | B37: F16 | C37: M4 – Gallery & Bot | D37: Sửa / xóa bình luận | E37: SC04 | F37: =IFERROR(INDEX('Checklist cover'!$F$5:$F$56,MATCH(B37,'Checklist cover'!$A$5:$A$56,0)),"") -> Nhóm 1 | G37: =IFERROR(VLOOKUP(F37,'Cấu hình'!$F$7:$G$9,2,FALSE()),"") -> Lâm Hoài An | H37: Xóa bình luận của mình | I37: Có bình luận | J37: Xóa | L37: Bình luận biến mất | M37: Use Case (luồng nghiệp vụ) | N37: Chức năng | O37: P1 | Q37: =IF(T37="Not Run","",G37) | T37: Not Run | W37: =IF(AND(T37="Fail",U37=""),"⚠ Fail nhưng thiếu Bug ID",IF(AND(T37<>"Not Run",T37<>"",R37=""),"⚠ Thiếu ngày test",IF(AND(T37="Pass",S37=""),"⚠ Thiếu kết quả thực tế","")))
A38: TC034 | B38: F16 | C38: M4 – Gallery & Bot | D38: Sửa / xóa bình luận | E38: SC04 | F38: =IFERROR(INDEX('Checklist cover'!$F$5:$F$56,MATCH(B38,'Checklist cover'!$A$5:$A$56,0)),"") -> Nhóm 1 | G38: =IFERROR(VLOOKUP(F38,'Cấu hình'!$F$7:$G$9,2,FALSE()),"") -> Lâm Hoài An | H38: Sửa/xóa bình luận của người khác (IDOR) | I38: 2 tài khoản A, B | J38: Đăng nhập B, gửi POST edit/delete với comment_id của A | K38: comment_id của A | L38: Bị từ chối, bình luận của A không đổi | M38: Experience-based (Error Guessing) | N38: Bảo mật | O38: P1 | Q38: =IF(T38="Not Run","",G38) | T38: Not Run | W38: =IF(AND(T38="Fail",U38=""),"⚠ Fail nhưng thiếu Bug ID",IF(AND(T38<>"Not Run",T38<>"",R38=""),"⚠ Thiếu ngày test",IF(AND(T38="Pass",S38=""),"⚠ Thiếu kết quả thực tế","")))
A39: TC035 | B39: F17 | C39: M4 – Gallery & Bot | D39: Thả tim ảnh Gallery | E39: SC03 | F39: =IFERROR(INDEX('Checklist cover'!$F$5:$F$56,MATCH(B39,'Checklist cover'!$A$5:$A$56,0)),"") -> Nhóm 1 | G39: =IFERROR(VLOOKUP(F39,'Cấu hình'!$F$7:$G$9,2,FALSE()),"") -> Lâm Hoài An | H39: Thả tim ảnh Gallery | I39: Đăng nhập user | J39: Bấm tim một ảnh, bấm lại | L39: Bật/tắt đúng, số lượng cập nhật, không tăng ảo | M39: Use Case (luồng nghiệp vụ) | N39: Chức năng | O39: P2 | Q39: =IF(T39="Not Run","",G39) | T39: Not Run | W39: =IF(AND(T39="Fail",U39=""),"⚠ Fail nhưng thiếu Bug ID",IF(AND(T39<>"Not Run",T39<>"",R39=""),"⚠ Thiếu ngày test",IF(AND(T39="Pass",S39=""),"⚠ Thiếu kết quả thực tế","")))
A40: TC036 | B40: F18 | C40: M5 – Ideas | D40: Gửi Idea | E40: SC05 | F40: =IFERROR(INDEX('Checklist cover'!$F$5:$F$56,MATCH(B40,'Checklist cover'!$A$5:$A$56,0)),"") -> Nhóm 1 | G40: =IFERROR(VLOOKUP(F40,'Cấu hình'!$F$7:$G$9,2,FALSE()),"") -> Lâm Hoài An | H40: Gửi idea hợp lệ | I40: Đăng nhập user | J40: Điền form, gửi | K40: tiêu đề + mô tả | L40: Idea mới trạng thái open, xuất hiện trong danh sách; nhận gem nhiệm vụ | M40: Use Case (luồng nghiệp vụ) | N40: Chức năng | O40: P1 | P40: AT05 | Q40: =IF(T40="Not Run","",G40) | T40: Not Run | W40: =IF(AND(T40="Fail",U40=""),"⚠ Fail nhưng thiếu Bug ID",IF(AND(T40<>"Not Run",T40<>"",R40=""),"⚠ Thiếu ngày test",IF(AND(T40="Pass",S40=""),"⚠ Thiếu kết quả thực tế","")))
A41: TC037 | B41: F18 | C41: M5 – Ideas | D41: Gửi Idea | E41: SC05 | F41: =IFERROR(INDEX('Checklist cover'!$F$5:$F$56,MATCH(B41,'Checklist cover'!$A$5:$A$56,0)),"") -> Nhóm 1 | G41: =IFERROR(VLOOKUP(F41,'Cấu hình'!$F$7:$G$9,2,FALSE()),"") -> Lâm Hoài An | H41: Gửi idea thiếu trường bắt buộc | I41: Đăng nhập user | J41: Để trống tiêu đề/mô tả | K41: (trống) | L41: Báo lỗi, không lưu | M41: Equivalence Partitioning | N41: Chức năng | O41: P2 | Q41: =IF(T41="Not Run","",G41) | T41: Not Run | W41: =IF(AND(T41="Fail",U41=""),"⚠ Fail nhưng thiếu Bug ID",IF(AND(T41<>"Not Run",T41<>"",R41=""),"⚠ Thiếu ngày test",IF(AND(T41="Pass",S41=""),"⚠ Thiếu kết quả thực tế","")))
...

Sheet Automation
A1: Automation Test – ANYN
A2: Công cụ: Playwright (hoặc Selenium) + PyTest. Mỗi script chạy 3 lần. Mã nguồn lưu ở 06_Automation_Test.
A4: AT ID | B4: TC ID | C4: Tên test case (tự động) | D4: Chức năng (tự động) | E4: File script | F4: Công cụ | G4: Người làm (tự động) | H4: Lần 1 | I4: Lần 2 | J4: Lần 3 | K4: Thời gian chạy (s) | L4: Ngày chạy | M4: Bằng chứng (log/ảnh) | N4: Ghi chú
A5: AT01 | B5: TC004 | C5: =IFERROR(INDEX('Test Cases'!$H$5:$H$300,MATCH(B5,'Test Cases'!$A$5:$A$300,0)),"") -> Đăng nhập đúng | D5: =IFERROR(INDEX('Test Cases'!$D$5:$D$300,MATCH(B5,'Test Cases'!$A$5:$A$300,0)),"") -> Đăng nhập | E5: tests/test_login_success.py | F5: Playwright + PyTest | G5: ='Cấu hình'!$B$10 -> Võ Trường Hải | H5: Not Run | I5: Not Run | J5: Not Run
A6: AT02 | B6: TC006 | C6: =IFERROR(INDEX('Test Cases'!$H$5:$H$300,MATCH(B6,'Test Cases'!$A$5:$A$300,0)),"") -> Sai 5 lần liên tiếp cùng email | D6: =IFERROR(INDEX('Test Cases'!$D$5:$D$300,MATCH(B6,'Test Cases'!$A$5:$A$300,0)),"") -> Chống dò mật khẩu (throttle) | E6: tests/test_login_lockout.py | F6: Playwright + PyTest | G6: ='Cấu hình'!$B$10 -> Võ Trường Hải | H6: Not Run | I6: Not Run | J6: Not Run
A7: AT03 | B7: TC014 | C7: =IFERROR(INDEX('Test Cases'!$H$5:$H$300,MATCH(B7,'Test Cases'!$A$5:$A$300,0)),"") -> Guest vào trang Admin | D7: =IFERROR(INDEX('Test Cases'!$D$5:$D$300,MATCH(B7,'Test Cases'!$A$5:$A$300,0)),"") -> Truy cập theo vai trò Guest/User/Admin | E7: tests/test_guest_admin_block.py | F7: Playwright + PyTest | G7: ='Cấu hình'!$B$10 -> Võ Trường Hải | H7: Not Run | I7: Not Run | J7: Not Run
A8: AT04 | B8: TC089 | C8: =IFERROR(INDEX('Test Cases'!$H$5:$H$300,MATCH(B8,'Test Cases'!$A$5:$A$300,0)),"") -> XSS lưu trong bình luận | D8: =IFERROR(INDEX('Test Cases'!$D$5:$D$300,MATCH(B8,'Test Cases'!$A$5:$A$300,0)),"") -> Chống XSS | E8: tests/test_comment_xss.py | F8: Playwright + PyTest | G8: ='Cấu hình'!$B$10 -> Võ Trường Hải | H8: Not Run | I8: Not Run | J8: Not Run
A9: AT05 | B9: TC036 | C9: =IFERROR(INDEX('Test Cases'!$H$5:$H$300,MATCH(B9,'Test Cases'!$A$5:$A$300,0)),"") -> Gửi idea hợp lệ | D9: =IFERROR(INDEX('Test Cases'!$D$5:$D$300,MATCH(B9,'Test Cases'!$A$5:$A$300,0)),"") -> Gửi Idea | E9: tests/test_submit_idea.py | F9: Playwright + PyTest | G9: ='Cấu hình'!$B$10 -> Võ Trường Hải | H9: Not Run | I9: Not Run | J9: Not Run
A10: AT06 | B10: TC064 | C10: =IFERROR(INDEX('Test Cases'!$H$5:$H$300,MATCH(B10,'Test Cases'!$A$5:$A$300,0)),"") -> Mua khi không đủ gem | D10: =IFERROR(INDEX('Test Cases'!$D$5:$D$300,MATCH(B10,'Test Cases'!$A$5:$A$300,0)),"") -> Mua vật phẩm | E10: tests/test_shop_insufficient_gems.py | F10: Playwright + PyTest | G10: ='Cấu hình'!$B$10 -> Võ Trường Hải | H10: Not Run | I10: Not Run | J10: Not Run
A14: Tổng hợp
A15: Số script | B15: =COUNTIF(A5:A12,"AT*") -> 6
A16: Pass (lần 3) | B16: =COUNTIF(J5:J12,"Pass") -> 0
A17: Fail (lần 3) | B17: =COUNTIF(J5:J12,"Fail") -> 0
A18: Tỷ lệ Pass | B18: =IF(B15=0,0,B16/B15) -> 0
A20: Lưu ý: Cột 'TC ID' phải trùng cột 'Tự động hóa' ở sheet Test Cases. Script lúc Pass lúc Fail (flaky) phải sửa trước khi nộp.

Sheet Non-functional
A1: Kiểm thử phi chức năng – ANYN
A2: A: Security · B: Performance. Chỉ test trên localhost của nhóm.
A3: A. SECURITY TESTING
A4: ID | B4: Hạng mục | C4: Mô tả kiểm tra | D4: TC liên quan | E4: Công cụ | F4: Người làm (tự động) | G4: Kết quả | H4: Mức rủi ro | I4: Phát hiện / Nhận xét | J4: Khuyến nghị | K4: Bằng chứng
A5: NF-S01 | B5: CSRF | C5: POST thiếu/sai csrf_token phải bị chặn 403 | D5: F45 | E5: Postman / curl | F5: ='Cấu hình'!$B$11 -> Châu Minh Tuệ | G5: Not Run
A6: NF-S02 | B6: XSS (lưu và phản chiếu) | C6: Payload trong bình luận, idea, bio, tiêu đề commission, tham số URL | D6: F46 | E6: Trình duyệt, DevTools | F6: ='Cấu hình'!$B$11 -> Châu Minh Tuệ | G6: Not Run
A7: NF-S03 | B7: SQL Injection | C7: Payload ở id, form đăng nhập, ô tìm kiếm | D7: F47 | E7: Thủ công, OWASP ZAP (tùy chọn) | F7: ='Cấu hình'!$B$11 -> Châu Minh Tuệ | G7: Not Run
A8: NF-S04 | B8: Upload tệp | C8: Đổi đuôi, ảnh chứa mã PHP, kích thước 0B/10MB | D8: F48 | E8: Thủ công | F8: ='Cấu hình'!$B$11 -> Châu Minh Tuệ | G8: Not Run
A9: NF-S05 | B9: Phân quyền / IDOR | C9: Sửa/xóa dữ liệu người khác, user vào trang admin | D9: F07, F16, F19, F20 | E9: Postman, trình duyệt | F9: ='Cấu hình'!$B$11 -> Châu Minh Tuệ | G9: Not Run
A10: NF-S06 | B10: Chống dò mật khẩu | C10: Khóa sau 5 lần/email, 20 lần/IP trong 15 phút | D10: F03 | E10: Thủ công / script | F10: ='Cấu hình'!$B$11 -> Châu Minh Tuệ | G10: Not Run
A11: NF-S07 | B11: Quản lý phiên và cookie | C11: HttpOnly, SameSite, Secure; đổi session ID sau đăng nhập | D11: F52, F02 | E11: DevTools | F11: ='Cấu hình'!$B$11 -> Châu Minh Tuệ | G11: Not Run
A12: NF-S08 | B12: Lộ thông tin và cấu hình | C12: Stack trace, DB root không mật khẩu, link reset ở chế độ development | D12: F52 | E12: Đọc cấu hình, DevTools | F12: ='Cấu hình'!$B$11 -> Châu Minh Tuệ | G12: Not Run
A13: NF-S09 | B13: Token đặt lại mật khẩu | C13: Token dùng một lần, hết hạn, bị sửa | D13: F06 | E13: Thủ công | F13: ='Cấu hình'!$B$11 -> Châu Minh Tuệ | G13: Not Run
A14: NF-S10 | B14: Bộ lọc nội dung | C14: Biến thể từ khóa bị cấm | D14: F49 | E14: Thủ công | F14: ='Cấu hình'!$B$11 -> Châu Minh Tuệ | G14: Not Run
A16: B. PERFORMANCE TESTING
A17: ID | B17: Trang / Luồng | C17: Kịch bản | D17: Công cụ | E17: Người làm (tự động) | F17: Số người dùng ảo | G17: TB phản hồi (ms) | H17: P95 (ms) | I17: Tỷ lệ lỗi (%) | J17: Điểm Lighthouse | K17: Nhận xét
A18: NF-P01 | B18: Trang chủ (index.php) | C18: Tải trang 1 người dùng | D18: Lighthouse | E18: ='Cấu hình'!$B$11 -> Châu Minh Tuệ
A19: NF-P02 | B19: Gallery (gallery.php) | C19: Tải trang 1 người dùng | D19: Lighthouse | E19: ='Cấu hình'!$B$11 -> Châu Minh Tuệ
A20: NF-P03 | B20: Chi tiết bot (bot_detail.php) | C20: Tải trang 1 người dùng | D20: Lighthouse | E20: ='Cấu hình'!$B$11 -> Châu Minh Tuệ
A21: NF-P04 | B21: Đăng nhập (login.php) | C21: 10 người dùng ảo đồng thời | D21: JMeter hoặc Locust | E21: ='Cấu hình'!$B$11 -> Châu Minh Tuệ
A22: NF-P05 | B22: Gallery | C22: 10 / 25 / 50 người dùng ảo trong 1 phút | D22: JMeter hoặc Locust | E22: ='Cấu hình'!$B$11 -> Châu Minh Tuệ
A23: NF-P06 | B23: Gợi ý tìm kiếm | C23: 25 người dùng ảo, truy vấn liên tục | D23: JMeter hoặc Locust | E23: ='Cấu hình'!$B$11 -> Châu Minh Tuệ
A25: Ngưỡng đề xuất: phản hồi TB ≤ 1000 ms, P95 ≤ 2000 ms, lỗi < 1%, điểm Lighthouse Performance ≥ 70.

Sheet Bug Log
A1: Bug Log – ANYN
A2: Mã BUG có sẵn. Chọn TC ID thì Module/Chức năng tự hiện. Nền vàng: nhập. Khang soát chất lượng mỗi tuần.
A4: Bug ID | B4: TC ID | C4: Module (tự động) | D4: Chức năng (tự động) | E4: Tiêu đề lỗi | F4: Các bước tái hiện | G4: Kết quả thực tế | H4: Kết quả mong đợi | I4: Severity | J4: Priority | K4: Trạng thái | L4: Người báo | M4: Người sửa | N4: Ngày báo | O4: Ngày đóng | P4: Tuổi lỗi (ngày) | Q4: Bằng chứng (ảnh/video)
A5: BUG-001 | C5: =IF(B5="","",IFERROR(INDEX('Test Cases'!$C$5:$C$300,MATCH(B5,'Test Cases'!$A$5:$A$300,0)),"")) | D5: =IF(B5="","",IFERROR(INDEX('Test Cases'!$D$5:$D$300,MATCH(B5,'Test Cases'!$A$5:$A$300,0)),"")) | P5: =IF(N5="","",IF(O5<>"",O5-N5,TODAY()-N5))
A6: BUG-002 | C6: =IF(B6="","",IFERROR(INDEX('Test Cases'!$C$5:$C$300,MATCH(B6,'Test Cases'!$A$5:$A$300,0)),"")) | D6: =IF(B6="","",IFERROR(INDEX('Test Cases'!$D$5:$D$300,MATCH(B6,'Test Cases'!$A$5:$A$300,0)),"")) | P6: =IF(N6="","",IF(O6<>"",O6-N6,TODAY()-N6))
A7: BUG-003 | C7: =IF(B7="","",IFERROR(INDEX('Test Cases'!$C$5:$C$300,MATCH(B7,'Test Cases'!$A$5:$A$300,0)),"")) | D7: =IF(B7="","",IFERROR(INDEX('Test Cases'!$D$5:$D$300,MATCH(B7,'Test Cases'!$A$5:$A$300,0)),"")) | P7: =IF(N7="","",IF(O7<>"",O7-N7,TODAY()-N7))
A8: BUG-004 | C8: =IF(B8="","",IFERROR(INDEX('Test Cases'!$C$5:$C$300,MATCH(B8,'Test Cases'!$A$5:$A$300,0)),"")) | D8: =IF(B8="","",IFERROR(INDEX('Test Cases'!$D$5:$D$300,MATCH(B8,'Test Cases'!$A$5:$A$300,0)),"")) | P8: =IF(N8="","",IF(O8<>"",O8-N8,TODAY()-N8))
A9: BUG-005 | C9: =IF(B9="","",IFERROR(INDEX('Test Cases'!$C$5:$C$300,MATCH(B9,'Test Cases'!$A$5:$A$300,0)),"")) | D9: =IF(B9="","",IFERROR(INDEX('Test Cases'!$D$5:$D$300,MATCH(B9,'Test Cases'!$A$5:$A$300,0)),"")) | P9: =IF(N9="","",IF(O9<>"",O9-N9,TODAY()-N9))
A10: BUG-006 | C10: =IF(B10="","",IFERROR(INDEX('Test Cases'!$C$5:$C$300,MATCH(B10,'Test Cases'!$A$5:$A$300,0)),"")) | D10: =IF(B10="","",IFERROR(INDEX('Test Cases'!$D$5:$D$300,MATCH(B10,'Test Cases'!$A$5:$A$300,0)),"")) | P10: =IF(N10="","",IF(O10<>"",O10-N10,TODAY()-N10))
A11: BUG-007 | C11: =IF(B11="","",IFERROR(INDEX('Test Cases'!$C$5:$C$300,MATCH(B11,'Test Cases'!$A$5:$A$300,0)),"")) | D11: =IF(B11="","",IFERROR(INDEX('Test Cases'!$D$5:$D$300,MATCH(B11,'Test Cases'!$A$5:$A$300,0)),"")) | P11: =IF(N11="","",IF(O11<>"",O11-N11,TODAY()-N11))
A12: BUG-008 | C12: =IF(B12="","",IFERROR(INDEX('Test Cases'!$C$5:$C$300,MATCH(B12,'Test Cases'!$A$5:$A$300,0)),"")) | D12: =IF(B12="","",IFERROR(INDEX('Test Cases'!$D$5:$D$300,MATCH(B12,'Test Cases'!$A$5:$A$300,0)),"")) | P12: =IF(N12="","",IF(O12<>"",O12-N12,TODAY()-N12))
A13: BUG-009 | C13: =IF(B13="","",IFERROR(INDEX('Test Cases'!$C$5:$C$300,MATCH(B13,'Test Cases'!$A$5:$A$300,0)),"")) | D13: =IF(B13="","",IFERROR(INDEX('Test Cases'!$D$5:$D$300,MATCH(B13,'Test Cases'!$A$5:$A$300,0)),"")) | P13: =IF(N13="","",IF(O13<>"",O13-N13,TODAY()-N13))
