Workbook

Sheet Hướng dẫn
A1: Cách dùng file này
A3: Mục đích | B3: Ghi kết quả chạy 49 test case của Nhóm 1 (M1–M5 + F49). File này là sản phẩm cho thư mục 04_Test_Execution/.
A4: Ô cần nhập (nền vàng) | B4: Kết quả thực tế · Trạng thái (chọn trong danh sách) · Bug ID · Ngày test · Ảnh chụp (tên file).
A5: Cột nền cam | B5: Điều chỉnh theo review: chỗ Review_TestCase_Nhom1 đề nghị sửa kết quả mong đợi hoặc ghi chú cách test. Đây là đề xuất chờ QA Lead duyệt, nên nếu hệ thống chạy khác bản gốc thì ghi rõ trong Kết quả thực tế.
A6: Trạng thái | B6: Not Run (mặc định) · Pass · Fail · Blocked · N/A. Trùng danh sách trong Checklist_TestCase.xlsx.
A7: Khi Fail | B7: Ghi Bug ID (BUG-xxx) và gửi cho Khang (người lập Bug Report). Chụp ảnh màn hình đặt tên theo TC ID, ví dụ TC001_fail.png.
A8: Thứ tự nên chạy | B8: P1 trước (lọc cột Ưu tiên = P1), rồi P2, P3. Theo Test Plan, test case P1 luôn chạy trước.
A9: Sheet Tổng hợp | B9: Tự đếm Pass/Fail/Not Run theo ưu tiên và module. Không gõ đè.
A10: Lưu ý dữ liệu | B10: Sao lưu CSDL trước mỗi đợt chạy (rủi ro 'dữ liệu test bị hỏng' trong Test Plan). Dùng tài khoản riêng cho mình.
A12: Ví dụ một dòng đã điền (minh hoạ, không nằm trong bảng dữ liệu)
A13: TC ID | B13: TC001
A14: Kết quả thực tế | B14: Hiện "Account created! You can now sign in.", ở lại trang đăng ký, DB có 1 bản ghi mới
A15: Trạng thái | B15: Pass
A16: Bug ID | B16: (để trống nếu Pass)
A17: Ngày test | B17: 13/10/2026
A18: Ảnh chụp (tên file) | B18: TC001_pass.png

Sheet Thực thi nhóm 1
A1: 04_Test_Execution – Nhóm chức năng 1 (M1–M5 + F49) – ANYN
A2: Người thực hiện: Lâm Hoài An (Functional Tester 1). Cột nền vàng là ô để nhập kết quả. Các cột còn lại lấy từ Checklist_TestCase.xlsx và Review_TestCase_Nhom1.xlsx, không gõ đè.
A4: TC ID | B4: Mã CN | C4: Module | D4: Chức năng | E4: Tiêu đề test case | F4: Ưu tiên | G4: Điều kiện tiên quyết | H4: Các bước thực hiện | I4: Dữ liệu test | J4: Kết quả mong đợi (bản gốc) | K4: Mức review | L4: Điều chỉnh theo review (nếu có) | M4: Kết quả thực tế | N4: Trạng thái | O4: Bug ID | P4: Ngày test | Q4: Ảnh chụp (tên file)
A5: TC001 | B5: F01 | C5: M1 – Tài khoản | D5: Đăng ký tài khoản | E5: Đăng ký thành công với dữ liệu hợp lệ | F5: P1 | G5: Chưa đăng nhập | H5: 1. Mở trang Đăng ký 2. Nhập username, email, mật khẩu hợp lệ 3. Bấm Đăng ký | I5: user: tester01 / tester01@mail.com / Test1234 | J5: Tạo tài khoản, chuyển sang đăng nhập hoặc vào trang chủ; role = user; DB có 1 bản ghi mới | K5: Sửa | L5: Kết quả mong đợi ghi "chuyển sang đăng nhập hoặc vào trang chủ". → Hiện "Account created! You can now sign in."; vẫn ở trang đăng ký, chưa đăng nhập; DB có 1 bản ghi role = user, email lưu chữ thường, mật khẩu là bcrypt hash. | N5: Not Run
A6: TC002 | B6: F01 | C6: M1 – Tài khoản | D6: Đăng ký tài khoản | E6: Đăng ký trùng email | F6: P1 | G6: Đã có tài khoản tester01@mail.com | H6: Đăng ký lại với email đã tồn tại, username khác | I6: email trùng | J6: Báo lỗi email đã tồn tại, không tạo tài khoản mới | K6: Sửa | L6: Mong đợi "báo lỗi email đã tồn tại" nhưng hệ thống dùng chung một thông báo. → Báo "Username or Email already in use."; không tạo tài khoản; thông báo không cho biết mục nào bị trùng. | N6: Not Run
A7: TC003 | B7: F01 | C7: M1 – Tài khoản | D7: Đăng ký tài khoản | E7: Mật khẩu ngắn hơn 8 ký tự | F7: P1 | H7: Nhập mật khẩu 7 ký tự | I7: Abc1234 | J7: Báo lỗi 'at least 8 characters' | N7: Not Run
A8: TC004 | B8: F02 | C8: M1 – Tài khoản | D8: Đăng nhập | E8: Đăng nhập đúng | F8: P1 | G8: Có tài khoản user | H8: Nhập email + mật khẩu đúng | I8: tester01 | J8: Đăng nhập thành công, header hiện tên/menu người dùng | N8: Not Run
A9: TC005 | B9: F02 | C9: M1 – Tài khoản | D9: Đăng nhập | E9: Đăng nhập sai mật khẩu | F9: P1 | G9: Có tài khoản user | H9: Nhập email đúng, mật khẩu sai | I9: sai mật khẩu | J9: Báo lỗi chung, không đăng nhập; không tiết lộ email có tồn tại | K9: Ghi chú | L9: Hiện "Invalid email or password." | N9: Not Run
A10: TC006 | B10: F03 | C10: M1 – Tài khoản | D10: Chống dò mật khẩu (throttle) | E10: Sai 5 lần liên tiếp cùng email | F10: P1 | G10: Có tài khoản user | H10: Đăng nhập sai mật khẩu 5 lần, lần 6 nhập đúng | I10: 15 phút | J10: Lần 6 bị chặn, có thông báo bị khóa tạm thời | K10: Ghi chú | L10: Lần 6 (dù nhập đúng) hiện "Too many failed attempts. Please wait 15 minutes and try again." | N10: Not Run
A11: TC007 | B11: F03 | C11: M1 – Tài khoản | D11: Chống dò mật khẩu (throttle) | E11: Hết thời gian khóa | F11: P3 | G11: Đang bị khóa | H11: Chờ qua 15 phút (hoặc sửa bản ghi login_attempts) rồi đăng nhập | J11: Đăng nhập lại được | N11: Not Run
A12: TC008 | B12: F04 | C12: M1 – Tài khoản | D12: Đăng xuất | E12: Đăng xuất | F12: P1 | G12: Đã đăng nhập | H12: Bấm Đăng xuất, sau đó nhấn nút Back của trình duyệt | J12: Session bị hủy; Back không vào lại được trang cần đăng nhập | K12: Sửa | L12: Nhấn Back có thể hiện trang từ bộ nhớ đệm trình duyệt dù phiên đã hủy, dễ bị nhầm là lỗi. → Sau Back, bấm F5 hoặc bấm một liên kết: phải bị chuyển/chặn vì chưa đăng nhập. Chỉ ghi lỗi nếu F5 vẫn vào được. | N12: Not Run
A13: TC009 | B13: F05 | C13: M1 – Tài khoản | D13: Quên mật khẩu | E13: Yêu cầu reset với email tồn tại | F13: P1 | G13: Có tài khoản | H13: Nhập email đúng ở trang Quên mật khẩu | I13: email hợp lệ | J13: Có thông báo đã gửi (hoặc hiện link reset khi APP_ENV=development) | N13: Not Run
A14: TC010 | B14: F05 | C14: M1 – Tài khoản | D14: Quên mật khẩu | E14: Yêu cầu reset với email không tồn tại | F14: P2 | H14: Nhập email chưa đăng ký | I14: none@mail.com | J14: Thông báo trung tính, không lộ email có tồn tại hay không | K14: Ghi chú | L14: Hiện "If that email is registered, a reset link has been sent. It expires in 30 minutes." giống trường hợp email tồn tại. | N14: Not Run
A15: TC011 | B15: F06 | C15: M1 – Tài khoản | D15: Đặt lại mật khẩu bằng token | E15: Reset bằng token hợp lệ | F15: P1 | G15: Có link reset | H15: Mở link, nhập mật khẩu mới hợp lệ | I15: Newpass123 | J15: Đổi mật khẩu thành công, đăng nhập được bằng mật khẩu mới | N15: Not Run
A16: TC012 | B16: F06 | C16: M1 – Tài khoản | D16: Đặt lại mật khẩu bằng token | E16: Dùng lại token đã sử dụng | F16: P1 | G16: Token đã dùng | H16: Mở lại link reset cũ | J16: Báo token không hợp lệ/đã dùng | K16: Ghi chú | L16: Hiện "This reset link is invalid or has expired." | N16: Not Run
A17: TC013 | B17: F07 | C17: M2 – Phân quyền | D17: Truy cập theo vai trò Guest/User/Admin | E17: Guest vào trang cần đăng nhập | F17: P1 | G17: Chưa đăng nhập | H17: Mở trực tiếp profile.php, commission.php, shop.php, my_commissions.php, submit_idea.php | I17: URL trực tiếp | J17: Chuyển hướng về trang đăng nhập | K17: Sửa | L17: Mong đợi "chuyển hướng về trang đăng nhập" đúng cho ít trang hơn thực tế. → profile.php: chuyển về login.php. commission/my_commissions/submit_idea: "Access Denied" + liên kết log in. shop/community_upload: "Sign in required". Không lộ dữ liệu người dùng. | N17: Not Run
A18: TC014 | B18: F07 | C18: M2 – Phân quyền | D18: Truy cập theo vai trò Guest/User/Admin | E18: Guest vào trang Admin | F18: P1 | G18: Chưa đăng nhập | H18: Mở admin_bots.php, admin_stats.php, admin_community.php, admin_groups.php, admin_add_bot.php | I18: URL trực tiếp | J18: Bị chặn (403 hoặc chuyển hướng), không lộ dữ liệu | K18: Sửa | L18: Mong đợi "403 hoặc chuyển hướng" quá rộng; hành vi mỗi trang khác nhau. → Ghi mong đợi theo từng trang (thông báo "Access Denied" hoặc chuyển về trang chủ) và ghi lại mã HTTP thực tế. | N18: Not Run
A19: TC015 | B19: F07 | C19: M2 – Phân quyền | D19: Truy cập theo vai trò Guest/User/Admin | E19: User thường vào trang Admin | F19: P1 | G19: Đăng nhập user | H19: Mở từng trang admin_* bằng URL | I19: URL trực tiếp | J19: Hiện 'Access Denied', mã 403 | K19: Sửa – có thể là lỗi | L19: Mong đợi theo thiết kế bảo mật: 403 và không lộ dữ liệu. Nếu thực tế là HTTP 200 kèm thông báo "Access Denied": ghi vào Bug Log (mức Low/Medium) và đánh dấu TC là Fail theo tiêu chí mã 403. admin_add_bot chuyển về trang chủ. | N19: Not Run
A20: TC016 | B20: F07 | C20: M2 – Phân quyền | D20: Truy cập theo vai trò Guest/User/Admin | E20: Admin truy cập đầy đủ | F20: P1 | G20: Đăng nhập admin | H20: Mở tất cả trang admin_* | J20: Truy cập bình thường | N20: Not Run
A21: TC017 | B21: F08 | C21: M3 – Trang chủ & Tìm kiếm | D21: Trang chủ | E21: Trang chủ hiển thị đầy đủ | F21: P1 | H21: Mở index.php | J21: Banner, menu, nội dung nổi bật tải đủ, không lỗi PHP/ảnh vỡ | K21: Ghi chú | L21: Ngoài banner và nội dung, đối chiếu các số liệu tổng quan với dữ liệu trong DB. | N21: Not Run
A22: TC018 | B22: F08 | C22: M3 – Trang chủ & Tìm kiếm | D22: Trang chủ | E22: Điều hướng menu | F22: P2 | H22: Bấm lần lượt các mục menu | J22: Mỗi mục dẫn đúng trang, không 404 | K22: Ghi chú | L22: Test lần lượt với Guest, user, admin; link quản trị chỉ hiện với admin. | N22: Not Run
A23: TC019 | B23: F09 | C23: M3 – Trang chủ & Tìm kiếm | D23: Gợi ý tìm kiếm | E23: Gợi ý tìm kiếm có kết quả | F23: P2 | H23: Gõ từ khóa có trong dữ liệu | I23: 1-3 ký tự đầu của tên bot | J23: Danh sách gợi ý hợp lý, định dạng đúng | K23: Ghi chú | L23: Trả JSON gồm id, name, image_url; chỉ khớp tên bot (không khớp mô tả). | N23: Not Run
A24: TC020 | B24: F09 | C24: M3 – Trang chủ & Tìm kiếm | D24: Gợi ý tìm kiếm | E24: Tìm kiếm không có kết quả | F24: P3 | H24: Gõ từ khóa không tồn tại | I24: zzzzqq | J24: Trả về rỗng hoặc thông báo, không lỗi | K24: Ghi chú | L24: Gợi ý: mảng rỗng []. Trang chủ: "No characters found. Try a different search." | N24: Not Run
A25: TC021 | B25: F10 | C25: M3 – Trang chủ & Tìm kiếm | D25: Trang giới thiệu | E25: Trang About | F25: P3 | H25: Mở about.php | J25: Nội dung hiển thị đúng, link hoạt động | N25: Not Run
A26: TC022 | B26: F11 | C26: M4 – Gallery & Bot | D26: Danh sách Gallery / lọc | E26: Xem danh sách Gallery | F26: P1 | H26: Mở gallery.php | J26: Ảnh tải đầy đủ, có phân nhóm | N26: Not Run
A27: TC023 | B27: F11 | C27: M4 – Gallery & Bot | D27: Danh sách Gallery / lọc | E27: Lọc/ phân trang Gallery | F27: P2 | H27: Dùng bộ lọc và chuyển trang | J27: Kết quả đúng bộ lọc, không trùng/mất ảnh | K27: Sửa | L27: Gallery không có bộ lọc hay phân trang phía server. → Đổi thành: mở rộng/thu gọn nhóm; nhóm trên 4 ảnh chỉ hiện 4 ảnh khi thu gọn, mở rộng thì đủ ảnh, không trùng/mất ảnh. | N27: Not Run
A28: TC024 | B28: F12 | C28: M4 – Gallery & Bot | D28: Chi tiết nhóm ảnh | E28: Mở nhóm ảnh hợp lệ | F28: P2 | H28: Bấm vào một nhóm | I28: id hợp lệ | J28: Hiển thị các ảnh thuộc nhóm | K28: Sửa | L28: Sai nội dung trang: group_detail.php hiển thị bot, không phải ảnh. → Hiển thị các bot (thẻ nhân vật kèm theme) thuộc bộ sưu tập đó. | N28: Not Run
A29: TC025 | B29: F12 | C29: M4 – Gallery & Bot | D29: Chi tiết nhóm ảnh | E29: Nhóm ảnh id không tồn tại / không hợp lệ | F29: P2 | H29: Mở group_detail.php?id=999999 và id=abc | I29: id lạ | J29: Thông báo không tìm thấy, không lỗi PHP/SQL | K29: Ghi chú | L29: id=999999 và id=abc: "Collection does not exist!"; không có tham số id: "Collection not found!". | N29: Not Run
A30: TC026 | B30: F13 | C30: M4 – Gallery & Bot | D30: Chi tiết Bot | E30: Xem chi tiết Bot | F30: P1 | H30: Mở bot_detail.php?id=<hợp lệ> | J30: Hiển thị thông tin, tag, điểm, bình luận | N30: Not Run
A31: TC027 | B31: F13 | C31: M4 – Gallery & Bot | D31: Chi tiết Bot | E31: Bot id không tồn tại | F31: P1 | H31: Mở id=999999 và id=' OR 1=1 | I31: id lạ | J31: Xử lý an toàn, không lộ lỗi SQL | K31: Ghi chú | L31: id=999999: thông báo không tìm thấy; id=' OR 1=1 bị ép thành 0 nên xử lý an toàn (chuyển về trang chủ hoặc báo không tìm thấy); không lộ lỗi SQL. | N31: Not Run
A32: TC028 | B32: F14 | C32: M4 – Gallery & Bot | D32: Chấm điểm Bot | E32: Chấm điểm hợp lệ | F32: P1 | G32: Đăng nhập user | H32: Chọn điểm và gửi | I32: điểm 1..5 | J32: Điểm được lưu, điểm trung bình cập nhật | N32: Not Run
A33: TC029 | B33: F14 | C33: M4 – Gallery & Bot | D33: Chấm điểm Bot | E33: Chấm điểm ngoài khoảng cho phép | F33: P1 | G33: Đăng nhập user | H33: Sửa giá trị score trong DevTools thành 0, 6, -1, 99, 'abc' | I33: score bất hợp lệ | J33: Bị từ chối, không lưu | K33: Sửa – có thể là lỗi | L33: Ghi nhận hành vi thực tế: điểm bị ép về 1 hoặc 5 và vẫn được lưu. Nếu nhóm coi dữ liệu sai nên bị từ chối thì ghi Bug Log (mức Low) và TC này Fail. | N33: Not Run
A34: TC030 | B34: F15 | C34: M4 – Gallery & Bot | D34: Thêm bình luận | E34: Thêm bình luận hợp lệ | F34: P1 | G34: Đăng nhập user | H34: Nhập nội dung, gửi | I34: Bình luận 1 dòng | J34: Bình luận xuất hiện đúng người, đúng thời gian | N34: Not Run
A35: TC031 | B35: F15 | C35: M4 – Gallery & Bot | D35: Thêm bình luận | E35: Bình luận rỗng / chỉ khoảng trắng | F35: P2 | G35: Đăng nhập user | H35: Gửi nội dung rỗng | I35: ' ' | J35: Bị từ chối | K35: Ghi chú | L35: Không tạo bình luận; không có thông báo lỗi (chỉ kiểm tra danh sách không đổi). | N35: Not Run
A36: TC032 | B36: F16 | C36: M4 – Gallery & Bot | D36: Sửa / xóa bình luận | E36: Sửa bình luận của mình | F36: P1 | G36: Có bình luận | H36: Sửa nội dung, lưu | J36: Nội dung cập nhật, hiện dấu 'đã sửa' (edited_at) | N36: Not Run
A37: TC033 | B37: F16 | C37: M4 – Gallery & Bot | D37: Sửa / xóa bình luận | E37: Xóa bình luận của mình | F37: P1 | G37: Có bình luận | H37: Xóa | J37: Bình luận biến mất | N37: Not Run
A38: TC034 | B38: F16 | C38: M4 – Gallery & Bot | D38: Sửa / xóa bình luận | E38: Sửa/xóa bình luận của người khác (IDOR) | F38: P1 | G38: 2 tài khoản A, B | H38: Đăng nhập B, gửi POST edit/delete với comment_id của A | I38: comment_id của A | J38: Bị từ chối, bình luận của A không đổi | N38: Not Run
A39: TC035 | B39: F17 | C39: M4 – Gallery & Bot | D39: Thả tim ảnh Gallery | E39: Thả tim ảnh Gallery | F39: P2 | G39: Đăng nhập user | H39: Bấm tim một ảnh, bấm lại | J39: Bật/tắt đúng, số lượng cập nhật, không tăng ảo | K39: Ghi chú | L39: Test từng loại: bật/tắt, đổi loại không cộng thêm; lần thả đầu được +2 gems (tối đa 10 lần/ngày). | N39: Not Run
A40: TC036 | B40: F18 | C40: M5 – Ideas | D40: Gửi Idea | E40: Gửi idea hợp lệ | F40: P1 | G40: Đăng nhập user | H40: Điền form, gửi | I40: tiêu đề + mô tả | J40: Idea mới trạng thái open, xuất hiện trong danh sách; nhận gem nhiệm vụ | N40: Not Run
A41: TC037 | B41: F18 | C41: M5 – Ideas | D41: Gửi Idea | E41: Gửi idea thiếu trường bắt buộc | F41: P2 | G41: Đăng nhập user | H41: Để trống tiêu đề/mô tả | I41: (trống) | J41: Báo lỗi, không lưu | K41: Ghi chú | L41: Gỡ required bằng DevTools; mong đợi thông báo trên. | N41: Not Run
...

Sheet Tổng hợp
A1: Tổng hợp thực thi – Nhóm 1 (tự cập nhật)
A2: Chỉ chép số vào báo cáo, không gõ đè. Cách tính giống sheet Test Summary trong Checklist_TestCase.xlsx (Đã thực thi = Tổng − Not Run).
A4: Tổng số TC | B4: =COUNTA('Thực thi nhóm 1'!$A$5:$A$53) -> 49
A5: Đã thực thi | B5: =B4-B10 -> 0
A6: Pass | B6: =COUNTIF('Thực thi nhóm 1'!$N$5:$N$53,"Pass") -> 0
A7: Fail | B7: =COUNTIF('Thực thi nhóm 1'!$N$5:$N$53,"Fail") -> 0
A8: Blocked | B8: =COUNTIF('Thực thi nhóm 1'!$N$5:$N$53,"Blocked") -> 0
A9: N/A | B9: =COUNTIF('Thực thi nhóm 1'!$N$5:$N$53,"N/A") -> 0
A10: Not Run | B10: =COUNTIF('Thực thi nhóm 1'!$N$5:$N$53,"Not Run") -> 49
A11: Tỷ lệ thực thi | B11: =IF(B4=0,0,B5/B4) -> 0
A12: Tỷ lệ Pass (trên số đã chạy) | B12: =IF(B5=0,0,B6/B5) -> 0
A13: Tỷ lệ Fail (trên số đã chạy) | B13: =IF(B5=0,0,B7/B5) -> 0
A15: Theo mức ưu tiên
A16: Ưu tiên | B16: Tổng | C16: Đã chạy | D16: Pass | E16: Fail
A17: P1 | B17: =COUNTIF('Thực thi nhóm 1'!$F$5:$F$53,A17) -> 33 | C17: =COUNTIFS('Thực thi nhóm 1'!$F$5:$F$53,A17,'Thực thi nhóm 1'!$N$5:$N$53,"<>Not Run") -> 0 | D17: =COUNTIFS('Thực thi nhóm 1'!$F$5:$F$53,A17,'Thực thi nhóm 1'!$N$5:$N$53,"Pass") -> 0 | E17: =COUNTIFS('Thực thi nhóm 1'!$F$5:$F$53,A17,'Thực thi nhóm 1'!$N$5:$N$53,"Fail") -> 0
A18: P2 | B18: =COUNTIF('Thực thi nhóm 1'!$F$5:$F$53,A18) -> 12 | C18: =COUNTIFS('Thực thi nhóm 1'!$F$5:$F$53,A18,'Thực thi nhóm 1'!$N$5:$N$53,"<>Not Run") -> 0 | D18: =COUNTIFS('Thực thi nhóm 1'!$F$5:$F$53,A18,'Thực thi nhóm 1'!$N$5:$N$53,"Pass") -> 0 | E18: =COUNTIFS('Thực thi nhóm 1'!$F$5:$F$53,A18,'Thực thi nhóm 1'!$N$5:$N$53,"Fail") -> 0
A19: P3 | B19: =COUNTIF('Thực thi nhóm 1'!$F$5:$F$53,A19) -> 4 | C19: =COUNTIFS('Thực thi nhóm 1'!$F$5:$F$53,A19,'Thực thi nhóm 1'!$N$5:$N$53,"<>Not Run") -> 0 | D19: =COUNTIFS('Thực thi nhóm 1'!$F$5:$F$53,A19,'Thực thi nhóm 1'!$N$5:$N$53,"Pass") -> 0 | E19: =COUNTIFS('Thực thi nhóm 1'!$F$5:$F$53,A19,'Thực thi nhóm 1'!$N$5:$N$53,"Fail") -> 0
A22: Theo module
A23: Module | B23: Tổng | C23: Đã chạy | D23: Pass | E23: Fail
A24: M1 – Tài khoản | B24: =COUNTIF('Thực thi nhóm 1'!$C$5:$C$53,A24) -> 12 | C24: =COUNTIFS('Thực thi nhóm 1'!$C$5:$C$53,A24,'Thực thi nhóm 1'!$N$5:$N$53,"<>Not Run") -> 0 | D24: =COUNTIFS('Thực thi nhóm 1'!$C$5:$C$53,A24,'Thực thi nhóm 1'!$N$5:$N$53,"Pass") -> 0 | E24: =COUNTIFS('Thực thi nhóm 1'!$C$5:$C$53,A24,'Thực thi nhóm 1'!$N$5:$N$53,"Fail") -> 0
A25: M2 – Phân quyền | B25: =COUNTIF('Thực thi nhóm 1'!$C$5:$C$53,A25) -> 4 | C25: =COUNTIFS('Thực thi nhóm 1'!$C$5:$C$53,A25,'Thực thi nhóm 1'!$N$5:$N$53,"<>Not Run") -> 0 | D25: =COUNTIFS('Thực thi nhóm 1'!$C$5:$C$53,A25,'Thực thi nhóm 1'!$N$5:$N$53,"Pass") -> 0 | E25: =COUNTIFS('Thực thi nhóm 1'!$C$5:$C$53,A25,'Thực thi nhóm 1'!$N$5:$N$53,"Fail") -> 0
A26: M3 – Trang chủ & Tìm kiếm | B26: =COUNTIF('Thực thi nhóm 1'!$C$5:$C$53,A26) -> 5 | C26: =COUNTIFS('Thực thi nhóm 1'!$C$5:$C$53,A26,'Thực thi nhóm 1'!$N$5:$N$53,"<>Not Run") -> 0 | D26: =COUNTIFS('Thực thi nhóm 1'!$C$5:$C$53,A26,'Thực thi nhóm 1'!$N$5:$N$53,"Pass") -> 0 | E26: =COUNTIFS('Thực thi nhóm 1'!$C$5:$C$53,A26,'Thực thi nhóm 1'!$N$5:$N$53,"Fail") -> 0
A27: M4 – Gallery & Bot | B27: =COUNTIF('Thực thi nhóm 1'!$C$5:$C$53,A27) -> 14 | C27: =COUNTIFS('Thực thi nhóm 1'!$C$5:$C$53,A27,'Thực thi nhóm 1'!$N$5:$N$53,"<>Not Run") -> 0 | D27: =COUNTIFS('Thực thi nhóm 1'!$C$5:$C$53,A27,'Thực thi nhóm 1'!$N$5:$N$53,"Pass") -> 0 | E27: =COUNTIFS('Thực thi nhóm 1'!$C$5:$C$53,A27,'Thực thi nhóm 1'!$N$5:$N$53,"Fail") -> 0
A28: M5 – Ideas | B28: =COUNTIF('Thực thi nhóm 1'!$C$5:$C$53,A28) -> 13 | C28: =COUNTIFS('Thực thi nhóm 1'!$C$5:$C$53,A28,'Thực thi nhóm 1'!$N$5:$N$53,"<>Not Run") -> 0 | D28: =COUNTIFS('Thực thi nhóm 1'!$C$5:$C$53,A28,'Thực thi nhóm 1'!$N$5:$N$53,"Pass") -> 0 | E28: =COUNTIFS('Thực thi nhóm 1'!$C$5:$C$53,A28,'Thực thi nhóm 1'!$N$5:$N$53,"Fail") -> 0
A29: M11 – Phi chức năng | B29: =COUNTIF('Thực thi nhóm 1'!$C$5:$C$53,A29) -> 1 | C29: =COUNTIFS('Thực thi nhóm 1'!$C$5:$C$53,A29,'Thực thi nhóm 1'!$N$5:$N$53,"<>Not Run") -> 0 | D29: =COUNTIFS('Thực thi nhóm 1'!$C$5:$C$53,A29,'Thực thi nhóm 1'!$N$5:$N$53,"Pass") -> 0 | E29: =COUNTIFS('Thực thi nhóm 1'!$C$5:$C$53,A29,'Thực thi nhóm 1'!$N$5:$N$53,"Fail") -> 0
